Workbook
Name Faecher: '⚙️ Konfiguration'!$A$13:$A$40
Name Klassen: '⚙️ Konfiguration'!$E$13:$E$27

Sheet ⚙️ Konfiguration
A1: ⚙️ KONFIGURATION – Schuljahr 2026/2027 | 10.08.2026 – 02.07.2027
A2: Stundenplan-Vorlagen (Mo–Fr) eintragen → Fach & Klasse erscheinen automatisch auf allen Tagesblättern.
A4: 📋 STUNDENPLAN-VORLAGEN – hier einmalig ausfüllen
A5: 📋 Montag-Vorlage → Fach und Klasse pro Lektion einmalig eintragen
A6: 📋 Dienstag-Vorlage → Fach und Klasse pro Lektion einmalig eintragen
A7: 📋 Mittwoch-Vorlage → Fach und Klasse pro Lektion einmalig eintragen
A8: 📋 Donnerstag-Vorlage → Fach und Klasse pro Lektion einmalig eintragen
A9: 📋 Freitag-Vorlage → Fach und Klasse pro Lektion einmalig eintragen
A11: 📚 FÄCHER | E11: 🏫 KLASSEN
A12: Kürzel | B12: Vollständiger Name | E12: Klasse
A13: Ads | B13: Angebot der Schule | E13: 7a
A14: h | B14: Halbklasse | E14: 7b
A15: b | B15: Berufliche Orientierung | E15: 7c
A16: ive | B16: Individ. Vertiefung/Erweiterung | E16: 8a
A17: Ba | B17: Basketball | E17: 8b
A18: Kb | B18: Keyboard Band | E18: 8c
A19: Bg | B19: Bildnerisches Gestalten | E19: 9a
A20: M | B20: Mathematik | E20: 9b
A21: BsB | B21: Bewegung und Sport Brünnen | E21: 9c
A22: MI | B22: Medien und Informatik | E22: 9d
A23: BsS | B23: Bewegung und Sport Schwabgut
A24: Mu | B24: Musik
A25: D | B25: Deutsch
A26: Nt | B26: Natur und Technik
A27: Daz | B27: Deutsch als Zweitsprache
A28: Rzg | B28: Räume, Zeiten, Gesellschaften
A29: E | B29: Englisch
A30: Ttg | B30: Textiles und Technisches Gestalten
A31: Erg | B31: Ethik, Religionen, Gemeinschaft
A32: Vo | B32: Volleyball
A33: F | B33: Französisch
A34: Wah | B34: Wirtschaft, Arbeit, Haushalt
A35: Pi | B35: Pilates

Sheet Übersicht
A1: JAHRESÜBERSICHT – Schuljahr 2026/2027 | 10.08.2026 – 02.07.2027
A2: 📋 Stundenplan-Vorlagen: Mo-Vorlage | Di-Vorlage | Mi-Vorlage | Do-Vorlage | Fr-Vorlage → Einmalig ausfüllen!
A3: KW | B3: Montag | C3: Dienstag | D3: Mittwoch | E3: Donnerstag | F3: Freitag
A4: KW 33 | B4: 10.08.2026 | C4: 11.08.2026 | D4: 12.08.2026 | E4: 13.08.2026 | F4: 14.08.2026
A5: KW 34 | B5: 17.08.2026 | C5: 18.08.2026 | D5: 19.08.2026 | E5: 20.08.2026 | F5: 21.08.2026
A6: KW 35 | B6: 24.08.2026 | C6: 25.08.2026 | D6: 26.08.2026 | E6: 27.08.2026 | F6: 28.08.2026
A7: KW 36 | B7: 31.08.2026 | C7: 01.09.2026 | D7: 02.09.2026 | E7: 03.09.2026 | F7: 04.09.2026
A8: KW 37 | B8: 07.09.2026 | C8: 08.09.2026 | D8: 09.09.2026 | E8: 10.09.2026 | F8: 11.09.2026
A9: KW 38 | B9: 14.09.2026 | C9: 15.09.2026 | D9: 16.09.2026 | E9: 17.09.2026 | F9: 18.09.2026
A10: KW 39 | B10: 21.09.2026 | C10: 22.09.2026 | D10: 23.09.2026 | E10: 24.09.2026 | F10: 25.09.2026
A11: KW 40 | B11: 28.09.2026 | C11: 29.09.2026 | D11: 30.09.2026 | E11: 01.10.2026 | F11: 02.10.2026
A12: KW 41 | B12: 05.10.2026 | C12: 06.10.2026 | D12: 07.10.2026 | E12: 08.10.2026 | F12: 09.10.2026
A13: KW 42 | B13: 12.10.2026 | C13: 13.10.2026 | D13: 14.10.2026 | E13: 15.10.2026 | F13: 16.10.2026
A14: KW 43 | B14: 19.10.2026 | C14: 20.10.2026 | D14: 21.10.2026 | E14: 22.10.2026 | F14: 23.10.2026
... A50: KW 26 | B50: 28.06.2027 | C50: 29.06.2027 | D50: 30.06.2027 | E50: 01.07.2027 | F50: 02.07.2027

Sheet Mo-Vorlage
A1: 📋 VORLAGE MONTAG – Typischer Stundenplan | Schuljahr 2026/2027
A2: ✏️ Fach und Klasse pro Lektion eintragen → wird automatisch auf alle Montage im Schuljahr übertragen. Bei Ausnahmen: direkt im Tagesblatt überschreiben.
A3: Lek. | B3: Zeit ✏️ | C3: Fach ▼ | D3: Klasse ▼ | E3: Bemerkung / Thema (optional)
A4: 1 | B4: 07:30–08:15
A5: 2 | B5: 08:20–09:05
A6: 3 | B6: 09:10–09:55
A7: 4 | B7: 10:25–11:10
A8: 5 | B8: 11:15–12:00 | E8: ⬇ MITTAGSPAUSE ⬇
A9: 6
A10: 7 | B10: 14:35–15:20
A11: 8 | B11: 15:30–16:15
A12: 9 | B12: 16:15–17:00

Sheet Di-Vorlage
A1: 📋 VORLAGE DIENSTAG – Typischer Stundenplan | Schuljahr 2026/2027
A2: ✏️ Fach und Klasse pro Lektion eintragen → wird automatisch auf alle Dienstage im Schuljahr übertragen. Bei Ausnahmen: direkt im Tagesblatt überschreiben.
A3: Lek. | B3: Zeit ✏️ | C3: Fach ▼ | D3: Klasse ▼ | E3: Bemerkung / Thema (optional)
A4: 1 | B4: 07:30–08:15
A5: 2 | B5: 08:20–09:05
A6: 3 | B6: 09:10–09:55
A7: 4 | B7: 10:25–11:10
A8: 5 | B8: 11:15–12:00 | E8: ⬇ MITTAGSPAUSE ⬇
A9: 6
A10: 7 | B10: 14:35–15:20
A11: 8 | B11: 15:30–16:15
A12: 9 | B12: 16:15–17:00

Sheet Mi-Vorlage
A1: 📋 VORLAGE MITTWOCH – Typischer Stundenplan | Schuljahr 2026/2027
A2: ✏️ Fach und Klasse pro Lektion eintragen → wird automatisch auf alle Mittwoche im Schuljahr übertragen. Bei Ausnahmen: direkt im Tagesblatt überschreiben.
A3: Lek. | B3: Zeit ✏️ | C3: Fach ▼ | D3: Klasse ▼ | E3: Bemerkung / Thema (optional)
A4: 1 | B4: 07:30–08:15
A5: 2 | B5: 08:20–09:05
A6: 3 | B6: 09:10–09:55
A7: 4 | B7: 10:25–11:10
A8: 5 | B8: 11:15–12:00 | E8: ⬇ MITTAGSPAUSE ⬇
A9: 6
A10: 7 | B10: 14:35–15:20
A11: 8 | B11: 15:30–16:15
A12: 9 | B12: 16:15–17:00

Sheet Do-Vorlage
A1: 📋 VORLAGE DONNERSTAG – Typischer Stundenplan | Schuljahr 2026/2027
A2: ✏️ Fach und Klasse pro Lektion eintragen → wird automatisch auf alle Donnerstage im Schuljahr übertragen. Bei Ausnahmen: direkt im Tagesblatt überschreiben.
A3: Lek. | B3: Zeit ✏️ | C3: Fach ▼ | D3: Klasse ▼ | E3: Bemerkung / Thema (optional)
A4: 1 | B4: 07:30–08:15
A5: 2 | B5: 08:20–09:05
A6: 3 | B6: 09:10–09:55
A7: 4 | B7: 10:25–11:10
A8: 5 | B8: 11:15–12:00 | E8: ⬇ MITTAGSPAUSE ⬇
A9: 6
A10: 7 | B10: 14:35–15:20
A11: 8 | B11: 15:30–16:15
A12: 9 | B12: 16:15–17:00

Sheet Fr-Vorlage
A1: 📋 VORLAGE FREITAG – Typischer Stundenplan | Schuljahr 2026/2027
A2: ✏️ Fach und Klasse pro Lektion eintragen → wird automatisch auf alle Freitage im Schuljahr übertragen. Bei Ausnahmen: direkt im Tagesblatt überschreiben.
A3: Lek. | B3: Zeit ✏️ | C3: Fach ▼ | D3: Klasse ▼ | E3: Bemerkung / Thema (optional)
A4: 1 | B4: 07:30–08:15
A5: 2 | B5: 08:20–09:05
A6: 3 | B6: 09:10–09:55
A7: 4 | B7: 10:25–11:10
A8: 5 | B8: 11:15–12:00 | E8: ⬇ MITTAGSPAUSE ⬇
A9: 6
A10: 7 | B10: 14:35–15:20
A11: 8 | B11: 15:30–16:15
A12: 9 | B12: 16:15–17:00

Sheet 10.08.2026
A1: TAGESAGENDA – Montag, 10.08.2026
A2: 📄 PDF exportieren: Datei → Exportieren → Als PDF/XPS | ✏️ Fach/Klasse aus Montag-Vorlage (gelb) – zum Überschreiben einfach eintippen
A3: Lehrperson:
A4: Zeit | B4: Unterrichtsphase | C4: Fach ▼ | D4: Klasse ▼ | E4: Inhalt / Beschreibung | F4: Materialien | G4: Differenzierung / Notizen
A5: ◀ Zurück zur Übersicht | E5: 📋 Montag-Vorlage bearbeiten
A6: =" 1. Lek. | "&'Mo-Vorlage'!$B$4 -> 1. Lek. | 07:30–08:15
B7: 🗂 Admin | C7: ='Mo-Vorlage'!$C$4 -> 0 | D7: ='Mo-Vorlage'!$D$4 -> 0
B8: 🎯 Lernziele
B9: 🚀 Einstieg
B10: 📝 Aufgaben / Erarbeitung / Vertiefung / Üben
B11: 🔒 Abschluss / Ergebnissicherung
A13: =" 2. Lek. | "&'Mo-Vorlage'!$B$5 -> 2. Lek. | 08:20–09:05
B14: 🗂 Admin | C14: ='Mo-Vorlage'!$C$5 -> 0 | D14: ='Mo-Vorlage'!$D$5 -> 0
B15: 🎯 Lernziele
B16: 🚀 Einstieg
B17: 📝 Aufgaben / Erarbeitung / Vertiefung / Üben
B18: 🔒 Abschluss / Ergebnissicherung
A20: =" 3. Lek. | "&'Mo-Vorlage'!$B$6 -> 3. Lek. | 09:10–09:55
B21: 🗂 Admin | C21: ='Mo-Vorlage'!$C$6 -> 0 | D21: ='Mo-Vorlage'!$D$6 -> 0
B22: 🎯 Lernziele
B23: 🚀 Einstieg
B24: 📝 Aufgaben / Erarbeitung / Vertiefung / Üben
B25: 🔒 Abschluss / Ergebnissicherung
A27: =" 4. Lek. | "&'Mo-Vorlage'!$B$7 -> 4. Lek. | 10:25–11:10
B28: 🗂 Admin | C28: ='Mo-Vorlage'!$C$7 -> 0 | D28: ='Mo-Vorlage'!$D$7 -> 0
B29: 🎯 Lernziele
B30: 🚀 Einstieg
B31: 📝 Aufgaben / Erarbeitung / Vertiefung / Üben
B32: 🔒 Abschluss / Ergebnissicherung
A34: =" 5. Lek. | "&'Mo-Vorlage'!$B$8 -> 5. Lek. | 11:15–12:00
B35: 🗂 Admin | C35: ='Mo-Vorlage'!$C$8 -> 0 | D35: ='Mo-Vorlage'!$D$8 -> 0
B36: 🎯 Lernziele
B37: 🚀 Einstieg
B38: 📝 Aufgaben / Erarbeitung / Vertiefung / Üben
B39: 🔒 Abschluss / Ergebnissicherung
A41: ── MITTAGSPAUSE
A42: =" 6. Lek. | "&'Mo-Vorlage'!$B$9 -> 6. Lek. |
B43: 🗂 Admin | C43: ='Mo-Vorlage'!$C$9 -> 0 | D43: ='Mo-Vorlage'!$D$9 -> 0
B44: 🎯 Lernziele
B45: 🚀 Einstieg
...

Sheet 11.08.2026
A1: TAGESAGENDA – Dienstag, 11.08.2026
A2: 📄 PDF exportieren: Datei → Exportieren → Als PDF/XPS | ✏️ Fach/Klasse aus Dienstag-Vorlage (gelb) – zum Überschreiben einfach eintippen
A3: Lehrperson:
A4: Zeit | B4: Unterrichtsphase | C4: Fach ▼ | D4: Klasse ▼ | E4: Inhalt / Beschreibung | F4: Materialien | G4: Differenzierung / Notizen
A5: ◀ Zurück zur Übersicht | E5: 📋 Dienstag-Vorlage bearbeiten
A6: =" 1. Lek. | "&'Di-Vorlage'!$B$4 -> 1. Lek. | 07:30–08:15
B7: 🗂 Admin | C7: ='Di-Vorlage'!$C$4 -> 0 | D7: ='Di-Vorlage'!$D$4 -> 0
B8: 🎯 Lernziele
B9: 🚀 Einstieg
B10: 📝 Aufgaben / Erarbeitung / Vertiefung / Üben
B11: 🔒 Abschluss / Ergebnissicherung
A13: =" 2. Lek. | "&'Di-Vorlage'!$B$5 -> 2. Lek. | 08:20–09:05
B14: 🗂 Admin | C14: ='Di-Vorlage'!$C$5 -> 0 | D14: ='Di-Vorlage'!$D$5 -> 0
B15: 🎯 Lernziele
B16: 🚀 Einstieg
B17: 📝 Aufgaben / Erarbeitung / Vertiefung / Üben
B18: 🔒 Abschluss / Ergebnissicherung
A20: =" 3. Lek. | "&'Di-Vorlage'!$B$6 -> 3. Lek. | 09:10–09:55
B21: 🗂 Admin | C21: ='Di-Vorlage'!$C$6 -> 0 | D21: ='Di-Vorlage'!$D$6 -> 0
B22: 🎯 Lernziele
B23: 🚀 Einstieg
B24: 📝 Aufgaben / Erarbeitung / Vertiefung / Üben
B25: 🔒 Abschluss / Ergebnissicherung
A27: =" 4. Lek. | "&'Di-Vorlage'!$B$7 -> 4. Lek. | 10:25–11:10
B28: 🗂 Admin | C28: ='Di-Vorlage'!$C$7 -> 0 | D28: ='Di-Vorlage'!$D$7 -> 0
B29: 🎯 Lernziele
B30: 🚀 Einstieg
B31: 📝 Aufgaben / Erarbeitung / Vertiefung / Üben
B32: 🔒 Abschluss / Ergebnissicherung
A34: =" 5. Lek. | "&'Di-Vorlage'!$B$8 -> 5. Lek. | 11:15–12:00
B35: 🗂 Admin | C35: ='Di-Vorlage'!$C$8 -> 0 | D35: ='Di-Vorlage'!$D$8 -> 0
B36: 🎯 Lernziele
B37: 🚀 Einstieg
B38: 📝 Aufgaben / Erarbeitung / Vertiefung / Üben
B39: 🔒 Abschluss / Ergebnissicherung
A41: ── MITTAGSPAUSE
A42: =" 6. Lek. | "&'Di-Vorlage'!$B$9 -> 6. Lek. |
B43: 🗂 Admin | C43: ='Di-Vorlage'!$C$9 -> 0 | D43: ='Di-Vorlage'!$D$9 -> 0
B44: 🎯 Lernziele
B45: 🚀 Einstieg
...

Sheet 12.08.2026
A1: TAGESAGENDA – Mittwoch, 12.08.2026
A2: 📄 PDF exportieren: Datei → Exportieren → Als PDF/XPS | ✏️ Fach/Klasse aus Mittwoch-Vorlage (gelb) – zum Überschreiben einfach eintippen
A3: Lehrperson:
A4: Zeit | B4: Unterrichtsphase | C4: Fach ▼ | D4: Klasse ▼ | E4: Inhalt / Beschreibung | F4: Materialien | G4: Differenzierung / Notizen
A5: ◀ Zurück zur Übersicht | E5: 📋 Mittwoch-Vorlage bearbeiten
A6: =" 1. Lek. | "&'Mi-Vorlage'!$B$4 -> 1. Lek. | 07:30–08:15
B7: 🗂 Admin | C7: ='Mi-Vorlage'!$C$4 -> 0 | D7: ='Mi-Vorlage'!$D$4 -> 0
B8: 🎯 Lernziele
B9: 🚀 Einstieg
B10: 📝 Aufgaben / Erarbeitung / Vertiefung / Üben
B11: 🔒 Abschluss / Ergebnissicherung
A13: =" 2. Lek. | "&'Mi-Vorlage'!$B$5 -> 2. Lek. | 08:20–09:05
B14: 🗂 Admin | C14: ='Mi-Vorlage'!$C$5 -> 0 | D14: ='Mi-Vorlage'!$D$5 -> 0
B15: 🎯 Lernziele
B16: 🚀 Einstieg
B17: 📝 Aufgaben / Erarbeitung / Vertiefung / Üben
B18: 🔒 Abschluss / Ergebnissicherung
A20: =" 3. Lek. | "&'Mi-Vorlage'!$B$6 -> 3. Lek. | 09:10–09:55
B21: 🗂 Admin | C21: ='Mi-Vorlage'!$C$6 -> 0 | D21: ='Mi-Vorlage'!$D$6 -> 0
B22: 🎯 Lernziele
B23: 🚀 Einstieg
B24: 📝 Aufgaben / Erarbeitung / Vertiefung / Üben
B25: 🔒 Abschluss / Ergebnissicherung
A27: =" 4. Lek. | "&'Mi-Vorlage'!$B$7 -> 4. Lek. | 10:25–11:10
B28: 🗂 Admin | C28: ='Mi-Vorlage'!$C$7 -> 0 | D28: ='Mi-Vorlage'!$D$7 -> 0
B29: 🎯 Lernziele
B30: 🚀 Einstieg
B31: 📝 Aufgaben / Erarbeitung / Vertiefung / Üben
B32: 🔒 Abschluss / Ergebnissicherung
A34: =" 5. Lek. | "&'Mi-Vorlage'!$B$8 -> 5. Lek. | 11:15–12:00
B35: 🗂 Admin | C35: ='Mi-Vorlage'!$C$8 -> 0 | D35: ='Mi-Vorlage'!$D$8 -> 0
B36: 🎯 Lernziele
B37: 🚀 Einstieg
B38: 📝 Aufgaben / Erarbeitung / Vertiefung / Üben
B39: 🔒 Abschluss / Ergebnissicherung
A41: ── MITTAGSPAUSE
A42: =" 6. Lek. | "&'Mi-Vorlage'!$B$9 -> 6. Lek. |
B43: 🗂 Admin | C43: ='Mi-Vorlage'!$C$9 -> 0 | D43: ='Mi-Vorlage'!$D$9 -> 0
B44: 🎯 Lernziele
B45: 🚀 Einstieg
...

Sheet 13.08.2026
A1: TAGESAGENDA – Donnerstag, 13.08.2026
A2: 📄 PDF exportieren: Datei → Exportieren → Als PDF/XPS | ✏️ Fach/Klasse aus Donnerstag-Vorlage (gelb) – zum Überschreiben einfach eintippen
A3: Lehrperson:
A4: Zeit | B4: Unterrichtsphase | C4: Fach ▼ | D4: Klasse ▼ | E4: Inhalt / Beschreibung | F4: Materialien | G4: Differenzierung / Notizen
A5: ◀ Zurück zur Übersicht | E5: 📋 Donnerstag-Vorlage bearbeiten
A6: =" 1. Lek. | "&'Do-Vorlage'!$B$4 -> 1. Lek. | 07:30–08:15
B7: 🗂 Admin | C7: ='Do-Vorlage'!$C$4 -> 0 | D7: ='Do-Vorlage'!$D$4 -> 0
B8: 🎯 Lernziele
B9: 🚀 Einstieg
B10: 📝 Aufgaben / Erarbeitung / Vertiefung / Üben
B11: 🔒 Abschluss / Ergebnissicherung
A13: =" 2. Lek. | "&'Do-Vorlage'!$B$5 -> 2. Lek. | 08:20–09:05
B14: 🗂 Admin | C14: ='Do-Vorlage'!$C$5 -> 0 | D14: ='Do-Vorlage'!$D$5 -> 0
B15: 🎯 Lernziele
B16: 🚀 Einstieg
B17: 📝 Aufgaben / Erarbeitung / Vertiefung / Üben
B18: 🔒 Abschluss / Ergebnissicherung
A20: =" 3. Lek. | "&'Do-Vorlage'!$B$6 -> 3. Lek. | 09:10–09:55
B21: 🗂 Admin | C21: ='Do-Vorlage'!$C$6 -> 0 | D21: ='Do-Vorlage'!$D$6 -> 0
B22: 🎯 Lernziele
B23: 🚀 Einstieg
B24: 📝 Aufgaben / Erarbeitung / Vertiefung / Üben
B25: 🔒 Abschluss / Ergebnissicherung
A27: =" 4. Lek. | "&'Do-Vorlage'!$B$7 -> 4. Lek. | 10:25–11:10
B28: 🗂 Admin | C28: ='Do-Vorlage'!$C$7 -> 0 | D28: ='Do-Vorlage'!$D$7 -> 0
B29: 🎯 Lernziele
B30: 🚀 Einstieg
B31: 📝 Aufgaben / Erarbeitung / Vertiefung / Üben
B32: 🔒 Abschluss / Ergebnissicherung
A34: =" 5. Lek. | "&'Do-Vorlage'!$B$8 -> 5. Lek. | 11:15–12:00
B35: 🗂 Admin | C35: ='Do-Vorlage'!$C$8 -> 0 | D35: ='Do-Vorlage'!$D$8 -> 0
B36: 🎯 Lernziele
B37: 🚀 Einstieg
B38: 📝 Aufgaben / Erarbeitung / Vertiefung / Üben
B39: 🔒 Abschluss / Ergebnissicherung
A41: ── MITTAGSPAUSE
A42: =" 6. Lek. | "&'Do-Vorlage'!$B$9 -> 6. Lek. |
B43: 🗂 Admin | C43: ='Do-Vorlage'!$C$9 -> 0 | D43: ='Do-Vorlage'!$D$9 -> 0
B44: 🎯 Lernziele
B45: 🚀 Einstieg
...

Sheet 14.08.2026
A1: TAGESAGENDA – Freitag, 14.08.2026
A2: 📄 PDF exportieren: Datei → Exportieren → Als PDF/XPS | ✏️ Fach/Klasse aus Freitag-Vorlage (gelb) – zum Überschreiben einfach eintippen
A3: Lehrperson:
A4: Zeit | B4: Unterrichtsphase | C4: Fach ▼ | D4: Klasse ▼ | E4: Inhalt / Beschreibung | F4: Materialien | G4: Differenzierung / Notizen
A5: ◀ Zurück zur Übersicht | E5: 📋 Freitag-Vorlage bearbeiten
A6: =" 1. Lek. | "&'Fr-Vorlage'!$B$4 -> 1. Lek. | 07:30–08:15
B7: 🗂 Admin | C7: ='Fr-Vorlage'!$C$4 -> 0 | D7: ='Fr-Vorlage'!$D$4 -> 0
B8: 🎯 Lernziele
B9: 🚀 Einstieg
B10: 📝 Aufgaben / Erarbeitung / Vertiefung / Üben
B11: 🔒 Abschluss / Ergebnissicherung
A13: =" 2. Lek. | "&'Fr-Vorlage'!$B$5 -> 2. Lek. | 08:20–09:05
B14: 🗂 Admin | C14: ='Fr-Vorlage'!$C$5 -> 0 | D14: ='Fr-Vorlage'!$D$5 -> 0
B15: 🎯 Lernziele
B16: 🚀 Einstieg
B17: 📝 Aufgaben / Erarbeitung / Vertiefung / Üben
B18: 🔒 Abschluss / Ergebnissicherung
A20: =" 3. Lek. | "&'Fr-Vorlage'!$B$6 -> 3. Lek. | 09:10–09:55
B21: 🗂 Admin | C21: ='Fr-Vorlage'!$C$6 -> 0 | D21: ='Fr-Vorlage'!$D$6 -> 0
B22: 🎯 Lernziele
B23: 🚀 Einstieg
B24: 📝 Aufgaben / Erarbeitung / Vertiefung / Üben
B25: 🔒 Abschluss / Ergebnissicherung
A27: =" 4. Lek. | "&'Fr-Vorlage'!$B$7 -> 4. Lek. | 10:25–11:10
B28: 🗂 Admin | C28: ='Fr-Vorlage'!$C$7 -> 0 | D28: ='Fr-Vorlage'!$D$7 -> 0
B29: 🎯 Lernziele
B30: 🚀 Einstieg
B31: 📝 Aufgaben / Erarbeitung / Vertiefung / Üben
B32: 🔒 Abschluss / Ergebnissicherung
A34: =" 5. Lek. | "&'Fr-Vorlage'!$B$8 -> 5. Lek. | 11:15–12:00
B35: 🗂 Admin | C35: ='Fr-Vorlage'!$C$8 -> 0 | D35: ='Fr-Vorlage'!$D$8 -> 0
B36: 🎯 Lernziele
B37: 🚀 Einstieg
B38: 📝 Aufgaben / Erarbeitung / Vertiefung / Üben
B39: 🔒 Abschluss / Ergebnissicherung
A41: ── MITTAGSPAUSE
A42: =" 6. Lek. | "&'Fr-Vorlage'!$B$9 -> 6. Lek. |
B43: 🗂 Admin | C43: ='Fr-Vorlage'!$C$9 -> 0 | D43: ='Fr-Vorlage'!$D$9 -> 0
B44: 🎯 Lernziele
B45: 🚀 Einstieg
...

Sheet 17.08.2026
A1: TAGESAGENDA – Montag, 17.08.2026
A2: 📄 PDF exportieren: Datei → Exportieren → Als PDF/XPS | ✏️ Fach/Klasse aus Montag-Vorlage (gelb) – zum Überschreiben einfach eintippen
A3: Lehrperson:
A4: Zeit | B4: Unterrichtsphase | C4: Fach ▼ | D4: Klasse ▼ | E4: Inhalt / Beschreibung | F4: Materialien | G4: Differenzierung / Notizen
A5: ◀ Zurück zur Übersicht | E5: 📋 Montag-Vorlage bearbeiten
A6: =" 1. Lek. | "&'Mo-Vorlage'!$B$4 -> 1. Lek. | 07:30–08:15
B7: 🗂 Admin | C7: ='Mo-Vorlage'!$C$4 -> 0 | D7: ='Mo-Vorlage'!$D$4 -> 0
B8: 🎯 Lernziele
B9: 🚀 Einstieg
B10: 📝 Aufgaben / Erarbeitung / Vertiefung / Üben
B11: 🔒 Abschluss / Ergebnissicherung
A13: =" 2. Lek. | "&'Mo-Vorlage'!$B$5 -> 2. Lek. | 08:20–09:05
B14: 🗂 Admin | C14: ='Mo-Vorlage'!$C$5 -> 0 | D14: ='Mo-Vorlage'!$D$5 -> 0
B15: 🎯 Lernziele
B16: 🚀 Einstieg
B17: 📝 Aufgaben / Erarbeitung / Vertiefung / Üben
B18: 🔒 Abschluss / Ergebnissicherung
A20: =" 3. Lek. | "&'Mo-Vorlage'!$B$6 -> 3. Lek. | 09:10–09:55
B21: 🗂 Admin | C21: ='Mo-Vorlage'!$C$6 -> 0 | D21: ='Mo-Vorlage'!$D$6 -> 0
B22: 🎯 Lernziele
B23: 🚀 Einstieg
B24: 📝 Aufgaben / Erarbeitung / Vertiefung / Üben
B25: 🔒 Abschluss / Ergebnissicherung
A27: =" 4. Lek. | "&'Mo-Vorlage'!$B$7 -> 4. Lek. | 10:25–11:10
B28: 🗂 Admin | C28: ='Mo-Vorlage'!$C$7 -> 0 | D28: ='Mo-Vorlage'!$D$7 -> 0
B29: 🎯 Lernziele
B30: 🚀 Einstieg
B31: 📝 Aufgaben / Erarbeitung / Vertiefung / Üben
B32: 🔒 Abschluss / Ergebnissicherung
A34: =" 5. Lek. | "&'Mo-Vorlage'!$B$8 -> 5. Lek. | 11:15–12:00
B35: 🗂 Admin | C35: ='Mo-Vorlage'!$C$8 -> 0 | D35: ='Mo-Vorlage'!$D$8 -> 0
B36: 🎯 Lernziele
B37: 🚀 Einstieg
B38: 📝 Aufgaben / Erarbeitung / Vertiefung / Üben
B39: 🔒 Abschluss / Ergebnissicherung
A41: ── MITTAGSPAUSE
A42: =" 6. Lek. | "&'Mo-Vorlage'!$B$9 -> 6. Lek. |
B43: 🗂 Admin | C43: ='Mo-Vorlage'!$C$9 -> 0 | D43: ='Mo-Vorlage'!$D$9 -> 0
B44: 🎯 Lernziele
B45: 🚀 Einstieg
...

Sheet 18.08.2026
A1: TAGESAGENDA – Dienstag, 18.08.2026
A2: 📄 PDF exportieren: Datei → Exportieren → Als PDF/XPS | ✏️ Fach/Klasse aus Dienstag-Vorlage (gelb) – zum Überschreiben einfach eintippen
A3: Lehrperson:
A4: Zeit | B4: Unterrichtsphase | C4: Fach ▼ | D4: Klasse ▼ | E4: Inhalt / Beschreibung | F4: Materialien | G4: Differenzierung / Notizen
A5: ◀ Zurück zur Übersicht | E5: 📋 Dienstag-Vorlage bearbeiten
A6: =" 1. Lek. | "&'Di-Vorlage'!$B$4 -> 1. Lek. | 07:30–08:15
B7: 🗂 Admin | C7: ='Di-Vorlage'!$C$4 -> 0 | D7: ='Di-Vorlage'!$D$4 -> 0
B8: 🎯 Lernziele
B9: 🚀 Einstieg
B10: 📝 Aufgaben / Erarbeitung / Vertiefung / Üben
B11: 🔒 Abschluss / Ergebnissicherung
A13: =" 2. Lek. | "&'Di-Vorlage'!$B$5 -> 2. Lek. | 08:20–09:05
B14: 🗂 Admin | C14: ='Di-Vorlage'!$C$5 -> 0 | D14: ='Di-Vorlage'!$D$5 -> 0
B15: 🎯 Lernziele
B16: 🚀 Einstieg
B17: 📝 Aufgaben / Erarbeitung / Vertiefung / Üben
B18: 🔒 Abschluss / Ergebnissicherung
A20: =" 3. Lek. | "&'Di-Vorlage'!$B$6 -> 3. Lek. | 09:10–09:55
B21: 🗂 Admin | C21: ='Di-Vorlage'!$C$6 -> 0 | D21: ='Di-Vorlage'!$D$6 -> 0
B22: 🎯 Lernziele
B23: 🚀 Einstieg
B24: 📝 Aufgaben / Erarbeitung / Vertiefung / Üben
B25: 🔒 Abschluss / Ergebnissicherung
A27: =" 4. Lek. | "&'Di-Vorlage'!$B$7 -> 4. Lek. | 10:25–11:10
B28: 🗂 Admin | C28: ='Di-Vorlage'!$C$7 -> 0 | D28: ='Di-Vorlage'!$D$7 -> 0
B29: 🎯 Lernziele
B30: 🚀 Einstieg
B31: 📝 Aufgaben / Erarbeitung / Vertiefung / Üben
B32: 🔒 Abschluss / Ergebnissicherung
A34: =" 5. Lek. | "&'Di-Vorlage'!$B$8 -> 5. Lek. | 11:15–12:00
B35: 🗂 Admin | C35: ='Di-Vorlage'!$C$8 -> 0 | D35: ='Di-Vorlage'!$D$8 -> 0
B36: 🎯 Lernziele
B37: 🚀 Einstieg
B38: 📝 Aufgaben / Erarbeitung / Vertiefung / Üben
B39: 🔒 Abschluss / Ergebnissicherung
A41: ── MITTAGSPAUSE
A42: =" 6. Lek. | "&'Di-Vorlage'!$B$9 -> 6. Lek. |
B43: 🗂 Admin | C43: ='Di-Vorlage'!$C$9 -> 0 | D43: ='Di-Vorlage'!$D$9 -> 0
B44: 🎯 Lernziele
B45: 🚀 Einstieg
...

Sheet 19.08.2026
A1: TAGESAGENDA – Mittwoch, 19.08.2026
A2: 📄 PDF exportieren: Datei → Exportieren → Als PDF/XPS | ✏️ Fach/Klasse aus Mittwoch-Vorlage (gelb) – zum Überschreiben einfach eintippen
A3: Lehrperson:
A4: Zeit | B4: Unterrichtsphase | C4: Fach ▼ | D4: Klasse ▼ | E4: Inhalt / Beschreibung | F4: Materialien | G4: Differenzierung / Notizen
A5: ◀ Zurück zur Übersicht | E5: 📋 Mittwoch-Vorlage bearbeiten
A6: =" 1. Lek. | "&'Mi-Vorlage'!$B$4 -> 1. Lek. | 07:30–08:15
B7: 🗂 Admin | C7: ='Mi-Vorlage'!$C$4 -> 0 | D7: ='Mi-Vorlage'!$D$4 -> 0
B8: 🎯 Lernziele
B9: 🚀 Einstieg
B10: 📝 Aufgaben / Erarbeitung / Vertiefung / Üben
B11: 🔒 Abschluss / Ergebnissicherung
A13: =" 2. Lek. | "&'Mi-Vorlage'!$B$5 -> 2. Lek. | 08:20–09:05
B14: 🗂 Admin | C14: ='Mi-Vorlage'!$C$5 -> 0 | D14: ='Mi-Vorlage'!$D$5 -> 0
B15: 🎯 Lernziele
B16: 🚀 Einstieg
B17: 📝 Aufgaben / Erarbeitung / Vertiefung / Üben
B18: 🔒 Abschluss / Ergebnissicherung
A20: =" 3. Lek. | "&'Mi-Vorlage'!$B$6 -> 3. Lek. | 09:10–09:55
B21: 🗂 Admin | C21: ='Mi-Vorlage'!$C$6 -> 0 | D21: ='Mi-Vorlage'!$D$6 -> 0
B22: 🎯 Lernziele
B23: 🚀 Einstieg
B24: 📝 Aufgaben / Erarbeitung / Vertiefung / Üben
B25: 🔒 Abschluss / Ergebnissicherung
A27: =" 4. Lek. | "&'Mi-Vorlage'!$B$7 -> 4. Lek. | 10:25–11:10
B28: 🗂 Admin | C28: ='Mi-Vorlage'!$C$7 -> 0 | D28: ='Mi-Vorlage'!$D$7 -> 0
B29: 🎯 Lernziele
B30: 🚀 Einstieg
B31: 📝 Aufgaben / Erarbeitung / Vertiefung / Üben
B32: 🔒 Abschluss / Ergebnissicherung
A34: =" 5. Lek. | "&'Mi-Vorlage'!$B$8 -> 5. Lek. | 11:15–12:00
B35: 🗂 Admin | C35: ='Mi-Vorlage'!$C$8 -> 0 | D35: ='Mi-Vorlage'!$D$8 -> 0
B36: 🎯 Lernziele
B37: 🚀 Einstieg
B38: 📝 Aufgaben / Erarbeitung / Vertiefung / Üben
B39: 🔒 Abschluss / Ergebnissicherung
A41: ── MITTAGSPAUSE
A42: =" 6. Lek. | "&'Mi-Vorlage'!$B$9 -> 6. Lek. |
B43: 🗂 Admin | C43: ='Mi-Vorlage'!$C$9 -> 0 | D43: ='Mi-Vorlage'!$D$9 -> 0
B44: 🎯 Lernziele
B45: 🚀 Einstieg
...

Sheet 20.08.2026
A1: TAGESAGENDA – Donnerstag, 20.08.2026
A2: 📄 PDF exportieren: Datei → Exportieren → Als PDF/XPS | ✏️ Fach/Klasse aus Donnerstag-Vorlage (gelb) – zum Überschreiben einfach eintippen
A3: Lehrperson:
A4: Zeit | B4: Unterrichtsphase | C4: Fach ▼ | D4: Klasse ▼ | E4: Inhalt / Beschreibung | F4: Materialien | G4: Differenzierung / Notizen
A5: ◀ Zurück zur Übersicht | E5: 📋 Donnerstag-Vorlage bearbeiten
A6: =" 1. Lek. | "&'Do-Vorlage'!$B$4 -> 1. Lek. | 07:30–08:15
B7: 🗂 Admin | C7: ='Do-Vorlage'!$C$4 -> 0 | D7: ='Do-Vorlage'!$D$4 -> 0
B8: 🎯 Lernziele
B9: 🚀 Einstieg
B10: 📝 Aufgaben / Erarbeitung / Vertiefung / Üben
B11: 🔒 Abschluss / Ergebnissicherung
A13: =" 2. Lek. | "&'Do-Vorlage'!$B$5 -> 2. Lek. | 08:20–09:05
B14: 🗂 Admin | C14: ='Do-Vorlage'!$C$5 -> 0 | D14: ='Do-Vorlage'!$D$5 -> 0
B15: 🎯 Lernziele
B16: 🚀 Einstieg
B17: 📝 Aufgaben / Erarbeitung / Vertiefung / Üben
B18: 🔒 Abschluss / Ergebnissicherung
A20: =" 3. Lek. | "&'Do-Vorlage'!$B$6 -> 3. Lek. | 09:10–09:55
B21: 🗂 Admin | C21: ='Do-Vorlage'!$C$6 -> 0 | D21: ='Do-Vorlage'!$D$6 -> 0
B22: 🎯 Lernziele
B23: 🚀 Einstieg
B24: 📝 Aufgaben / Erarbeitung / Vertiefung / Üben
B25: 🔒 Abschluss / Ergebnissicherung
A27: =" 4. Lek. | "&'Do-Vorlage'!$B$7 -> 4. Lek. | 10:25–11:10
B28: 🗂 Admin | C28: ='Do-Vorlage'!$C$7 -> 0 | D28: ='Do-Vorlage'!$D$7 -> 0
B29: 🎯 Lernziele
B30: 🚀 Einstieg
B31: 📝 Aufgaben / Erarbeitung / Vertiefung / Üben
B32: 🔒 Abschluss / Ergebnissicherung
A34: =" 5. Lek. | "&'Do-Vorlage'!$B$8 -> 5. Lek. | 11:15–12:00
B35: 🗂 Admin | C35: ='Do-Vorlage'!$C$8 -> 0 | D35: ='Do-Vorlage'!$D$8 -> 0
B36: 🎯 Lernziele
B37: 🚀 Einstieg
B38: 📝 Aufgaben / Erarbeitung / Vertiefung / Üben
B39: 🔒 Abschluss / Ergebnissicherung
A41: ── MITTAGSPAUSE
A42: =" 6. Lek. | "&'Do-Vorlage'!$B$9 -> 6. Lek. |
B43: 🗂 Admin | C43: ='Do-Vorlage'!$C$9 -> 0 | D43: ='Do-Vorlage'!$D$9 -> 0
B44: 🎯 Lernziele
B45: 🚀 Einstieg
...

Sheet 21.08.2026
A1: TAGESAGENDA – Freitag, 21.08.2026
A2: 📄 PDF exportieren: Datei → Exportieren → Als PDF/XPS | ✏️ Fach/Klasse aus Freitag-Vorlage (gelb) – zum Überschreiben einfach eintippen
A3: Lehrperson:
A4: Zeit | B4: Unterrichtsphase | C4: Fach ▼ | D4: Klasse ▼ | E4: Inhalt / Beschreibung | F4: Materialien | G4: Differenzierung / Notizen
A5: ◀ Zurück zur Übersicht | E5: 📋 Freitag-Vorlage bearbeiten
A6: =" 1. Lek. | "&'Fr-Vorlage'!$B$4 -> 1. Lek. | 07:30–08:15
B7: 🗂 Admin | C7: ='Fr-Vorlage'!$C$4 -> 0 | D7: ='Fr-Vorlage'!$D$4 -> 0
B8: 🎯 Lernziele
B9: 🚀 Einstieg
B10: 📝 Aufgaben / Erarbeitung / Vertiefung / Üben
B11: 🔒 Abschluss / Ergebnissicherung
A13: =" 2. Lek. | "&'Fr-Vorlage'!$B$5 -> 2. Lek. | 08:20–09:05
B14: 🗂 Admin | C14: ='Fr-Vorlage'!$C$5 -> 0 | D14: ='Fr-Vorlage'!$D$5 -> 0
B15: 🎯 Lernziele
B16: 🚀 Einstieg
B17: 📝 Aufgaben / Erarbeitung / Vertiefung / Üben
B18: 🔒 Abschluss / Ergebnissicherung
A20: =" 3. Lek. | "&'Fr-Vorlage'!$B$6 -> 3. Lek. | 09:10–09:55
B21: 🗂 Admin | C21: ='Fr-Vorlage'!$C$6 -> 0 | D21: ='Fr-Vorlage'!$D$6 -> 0
B22: 🎯 Lernziele
B23: 🚀 Einstieg
B24: 📝 Aufgaben / Erarbeitung / Vertiefung / Üben
B25: 🔒 Abschluss / Ergebnissicherung
A27: =" 4. Lek. | "&'Fr-Vorlage'!$B$7 -> 4. Lek. | 10:25–11:10
B28: 🗂 Admin | C28: ='Fr-Vorlage'!$C$7 -> 0 | D28: ='Fr-Vorlage'!$D$7 -> 0
B29: 🎯 Lernziele
B30: 🚀 Einstieg
B31: 📝 Aufgaben / Erarbeitung / Vertiefung / Üben
B32: 🔒 Abschluss / Ergebnissicherung
A34: =" 5. Lek. | "&'Fr-Vorlage'!$B$8 -> 5. Lek. | 11:15–12:00
B35: 🗂 Admin | C35: ='Fr-Vorlage'!$C$8 -> 0 | D35: ='Fr-Vorlage'!$D$8 -> 0
B36: 🎯 Lernziele
B37: 🚀 Einstieg
B38: 📝 Aufgaben / Erarbeitung / Vertiefung / Üben
B39: 🔒 Abschluss / Ergebnissicherung
A41: ── MITTAGSPAUSE
A42: =" 6. Lek. | "&'Fr-Vorlage'!$B$9 -> 6. Lek. |
B43: 🗂 Admin | C43: ='Fr-Vorlage'!$C$9 -> 0 | D43: ='Fr-Vorlage'!$D$9 -> 0
B44: 🎯 Lernziele
B45: 🚀 Einstieg
...

Sheet 24.08.2026
A1: TAGESAGENDA – Montag, 24.08.2026
A2: 📄 PDF exportieren: Datei → Exportieren → Als PDF/XPS | ✏️ Fach/Klasse aus Montag-Vorlage (gelb) – zum Überschreiben einfach eintippen
A3: Lehrperson:
A4: Zeit | B4: Unterrichtsphase | C4: Fach ▼ | D4: Klasse ▼ | E4: Inhalt / Beschreibung | F4: Materialien | G4: Differenzierung / Notizen
A5: ◀ Zurück zur Übersicht | E5: 📋 Montag-Vorlage bearbeiten
A6: =" 1. Lek. | "&'Mo-Vorlage'!$B$4 -> 1. Lek. | 07:30–08:15
B7: 🗂 Admin | C7: ='Mo-Vorlage'!$C$4 -> 0 | D7: ='Mo-Vorlage'!$D$4 -> 0
B8: 🎯 Lernziele
B9: 🚀 Einstieg
B10: 📝 Aufgaben / Erarbeitung / Vertiefung / Üben
B11: 🔒 Abschluss / Ergebnissicherung
A13: =" 2. Lek. | "&'Mo-Vorlage'!$B$5 -> 2. Lek. | 08:20–09:05
B14: 🗂 Admin | C14: ='Mo-Vorlage'!$C$5 -> 0 | D14: ='Mo-Vorlage'!$D$5 -> 0
B15: 🎯 Lernziele
B16: 🚀 Einstieg
B17: 📝 Aufgaben / Erarbeitung / Vertiefung / Üben
B18: 🔒 Abschluss / Ergebnissicherung
A20: =" 3. Lek. | "&'Mo-Vorlage'!$B$6 -> 3. Lek. | 09:10–09:55
B21: 🗂 Admin | C21: ='Mo-Vorlage'!$C$6 -> 0 | D21: ='Mo-Vorlage'!$D$6 -> 0
B22: 🎯 Lernziele
B23: 🚀 Einstieg
B24: 📝 Aufgaben / Erarbeitung / Vertiefung / Üben
B25: 🔒 Abschluss / Ergebnissicherung
A27: =" 4. Lek. | "&'Mo-Vorlage'!$B$7 -> 4. Lek. | 10:25–11:10
B28: 🗂 Admin | C28: ='Mo-Vorlage'!$C$7 -> 0 | D28: ='Mo-Vorlage'!$D$7 -> 0
B29: 🎯 Lernziele
B30: 🚀 Einstieg
B31: 📝 Aufgaben / Erarbeitung / Vertiefung / Üben
B32: 🔒 Abschluss / Ergebnissicherung
A34: =" 5. Lek. | "&'Mo-Vorlage'!$B$8 -> 5. Lek. | 11:15–12:00
B35: 🗂 Admin | C35: ='Mo-Vorlage'!$C$8 -> 0 | D35: ='Mo-Vorlage'!$D$8 -> 0
B36: 🎯 Lernziele
B37: 🚀 Einstieg
B38: 📝 Aufgaben / Erarbeitung / Vertiefung / Üben
B39: 🔒 Abschluss / Ergebnissicherung
A41: ── MITTAGSPAUSE
A42: =" 6. Lek. | "&'Mo-Vorlage'!$B$9 -> 6. Lek. |
B43: 🗂 Admin | C43: ='Mo-Vorlage'!$C$9 -> 0 | D43: ='Mo-Vorlage'!$D$9 -> 0
B44: 🎯 Lernziele
B45: 🚀 Einstieg
...

Sheet 25.08.2026
A1: TAGESAGENDA – Dienstag, 25.08.2026
A2: 📄 PDF exportieren: Datei → Exportieren → Als PDF/XPS | ✏️ Fach/Klasse aus Dienstag-Vorlage (gelb) – zum Überschreiben einfach eintippen
A3: Lehrperson:
A4: Zeit | B4: Unterrichtsphase | C4: Fach ▼ | D4: Klasse ▼ | E4: Inhalt / Beschreibung | F4: Materialien | G4: Differenzierung / Notizen
A5: ◀ Zurück zur Übersicht | E5: 📋 Dienstag-Vorlage bearbeiten
A6: =" 1. Lek. | "&'Di-Vorlage'!$B$4 -> 1. Lek. | 07:30–08:15
B7: 🗂 Admin | C7: ='Di-Vorlage'!$C$4 -> 0 | D7: ='Di-Vorlage'!$D$4 -> 0
B8: 🎯 Lernziele
B9: 🚀 Einstieg
B10: 📝 Aufgaben / Erarbeitung / Vertiefung / Üben
B11: 🔒 Abschluss / Ergebnissicherung
A13: =" 2. Lek. | "&'Di-Vorlage'!$B$5 -> 2. Lek. | 08:20–09:05
B14: 🗂 Admin | C14: ='Di-Vorlage'!$C$5 -> 0 | D14: ='Di-Vorlage'!$D$5 -> 0
B15: 🎯 Lernziele
B16: 🚀 Einstieg
B17: 📝 Aufgaben / Erarbeitung / Vertiefung / Üben
B18: 🔒 Abschluss / Ergebnissicherung
A20: =" 3. Lek. | "&'Di-Vorlage'!$B$6 -> 3. Lek. | 09:10–09:55
B21: 🗂 Admin | C21: ='Di-Vorlage'!$C$6 -> 0 | D21: ='Di-Vorlage'!$D$6 -> 0
B22: 🎯 Lernziele
B23: 🚀 Einstieg
B24: 📝 Aufgaben / Erarbeitung / Vertiefung / Üben
B25: 🔒 Abschluss / Ergebnissicherung
A27: =" 4. Lek. | "&'Di-Vorlage'!$B$7 -> 4. Lek. | 10:25–11:10
B28: 🗂 Admin | C28: ='Di-Vorlage'!$C$7 -> 0 | D28: ='Di-Vorlage'!$D$7 -> 0
B29: 🎯 Lernziele
B30: 🚀 Einstieg
B31: 📝 Aufgaben / Erarbeitung / Vertiefung / Üben
B32: 🔒 Abschluss / Ergebnissicherung
A34: =" 5. Lek. | "&'Di-Vorlage'!$B$8 -> 5. Lek. | 11:15–12:00
B35: 🗂 Admin | C35: ='Di-Vorlage'!$C$8 -> 0 | D35: ='Di-Vorlage'!$D$8 -> 0
B36: 🎯 Lernziele
B37: 🚀 Einstieg
B38: 📝 Aufgaben / Erarbeitung / Vertiefung / Üben
B39: 🔒 Abschluss / Ergebnissicherung
A41: ── MITTAGSPAUSE
A42: =" 6. Lek. | "&'Di-Vorlage'!$B$9 -> 6. Lek. |
B43: 🗂 Admin | C43: ='Di-Vorlage'!$C$9 -> 0 | D43: ='Di-Vorlage'!$D$9 -> 0
B44: 🎯 Lernziele
B45: 🚀 Einstieg
...

Sheet 26.08.2026
A1: TAGESAGENDA – Mittwoch, 26.08.2026
A2: 📄 PDF exportieren: Datei → Exportieren → Als PDF/XPS | ✏️ Fach/Klasse aus Mittwoch-Vorlage (gelb) – zum Überschreiben einfach eintippen
A3: Lehrperson:
A4: Zeit | B4: Unterrichtsphase | C4: Fach ▼ | D4: Klasse ▼ | E4: Inhalt / Beschreibung | F4: Materialien | G4: Differenzierung / Notizen
A5: ◀ Zurück zur Übersicht | E5: 📋 Mittwoch-Vorlage bearbeiten
A6: =" 1. Lek. | "&'Mi-Vorlage'!$B$4 -> 1. Lek. | 07:30–08:15
B7: 🗂 Admin | C7: ='Mi-Vorlage'!$C$4 -> 0 | D7: ='Mi-Vorlage'!$D$4 -> 0
B8: 🎯 Lernziele
B9: 🚀 Einstieg
B10: 📝 Aufgaben / Erarbeitung / Vertiefung / Üben
B11: 🔒 Abschluss / Ergebnissicherung
A13: =" 2. Lek. | "&'Mi-Vorlage'!$B$5 -> 2. Lek. | 08:20–09:05
B14: 🗂 Admin | C14: ='Mi-Vorlage'!$C$5 -> 0 | D14: ='Mi-Vorlage'!$D$5 -> 0
B15: 🎯 Lernziele
B16: 🚀 Einstieg
B17: 📝 Aufgaben / Erarbeitung / Vertiefung / Üben
B18: 🔒 Abschluss / Ergebnissicherung
A20: =" 3. Lek. | "&'Mi-Vorlage'!$B$6 -> 3. Lek. | 09:10–09:55
B21: 🗂 Admin | C21: ='Mi-Vorlage'!$C$6 -> 0 | D21: ='Mi-Vorlage'!$D$6 -> 0
B22: 🎯 Lernziele
B23: 🚀 Einstieg
B24: 📝 Aufgaben / Erarbeitung / Vertiefung / Üben
B25: 🔒 Abschluss / Ergebnissicherung
A27: =" 4. Lek. | "&'Mi-Vorlage'!$B$7 -> 4. Lek. | 10:25–11:10
B28: 🗂 Admin | C28: ='Mi-Vorlage'!$C$7 -> 0 | D28: ='Mi-Vorlage'!$D$7 -> 0
B29: 🎯 Lernziele
B30: 🚀 Einstieg
B31: 📝 Aufgaben / Erarbeitung / Vertiefung / Üben
B32: 🔒 Abschluss / Ergebnissicherung
A34: =" 5. Lek. | "&'Mi-Vorlage'!$B$8 -> 5. Lek. | 11:15–12:00
B35: 🗂 Admin | C35: ='Mi-Vorlage'!$C$8 -> 0 | D35: ='Mi-Vorlage'!$D$8 -> 0
B36: 🎯 Lernziele
B37: 🚀 Einstieg
B38: 📝 Aufgaben / Erarbeitung / Vertiefung / Üben
B39: 🔒 Abschluss / Ergebnissicherung
A41: ── MITTAGSPAUSE
A42: =" 6. Lek. | "&'Mi-Vorlage'!$B$9 -> 6. Lek. |
B43: 🗂 Admin | C43: ='Mi-Vorlage'!$C$9 -> 0 | D43: ='Mi-Vorlage'!$D$9 -> 0
B44: 🎯 Lernziele
B45: 🚀 Einstieg
...

Sheet 27.08.2026
A1: TAGESAGENDA – Donnerstag, 27.08.2026
A2: 📄 PDF exportieren: Datei → Exportieren → Als PDF/XPS | ✏️ Fach/Klasse aus Donnerstag-Vorlage (gelb) – zum Überschreiben einfach eintippen
A3: Lehrperson:
A4: Zeit | B4: Unterrichtsphase | C4: Fach ▼ | D4: Klasse ▼ | E4: Inhalt / Beschreibung | F4: Materialien | G4: Differenzierung / Notizen
A5: ◀ Zurück zur Übersicht | E5: 📋 Donnerstag-Vorlage bearbeiten
A6: =" 1. Lek. | "&'Do-Vorlage'!$B$4 -> 1. Lek. | 07:30–08:15
B7: 🗂 Admin | C7: ='Do-Vorlage'!$C$4 -> 0 | D7: ='Do-Vorlage'!$D$4 -> 0
B8: 🎯 Lernziele
B9: 🚀 Einstieg
B10: 📝 Aufgaben / Erarbeitung / Vertiefung / Üben
B11: 🔒 Abschluss / Ergebnissicherung
A13: =" 2. Lek. | "&'Do-Vorlage'!$B$5 -> 2. Lek. | 08:20–09:05
B14: 🗂 Admin | C14: ='Do-Vorlage'!$C$5 -> 0 | D14: ='Do-Vorlage'!$D$5 -> 0
B15: 🎯 Lernziele
B16: 🚀 Einstieg
B17: 📝 Aufgaben / Erarbeitung / Vertiefung / Üben
B18: 🔒 Abschluss / Ergebnissicherung
A20: =" 3. Lek. | "&'Do-Vorlage'!$B$6 -> 3. Lek. | 09:10–09:55
B21: 🗂 Admin | C21: ='Do-Vorlage'!$C$6 -> 0 | D21: ='Do-Vorlage'!$D$6 -> 0
B22: 🎯 Lernziele
B23: 🚀 Einstieg
B24: 📝 Aufgaben / Erarbeitung / Vertiefung / Üben
B25: 🔒 Abschluss / Ergebnissicherung
A27: =" 4. Lek. | "&'Do-Vorlage'!$B$7 -> 4. Lek. | 10:25–11:10
B28: 🗂 Admin | C28: ='Do-Vorlage'!$C$7 -> 0 | D28: ='Do-Vorlage'!$D$7 -> 0
B29: 🎯 Lernziele
B30: 🚀 Einstieg
B31: 📝 Aufgaben / Erarbeitung / Vertiefung / Üben
B32: 🔒 Abschluss / Ergebnissicherung
A34: =" 5. Lek. | "&'Do-Vorlage'!$B$8 -> 5. Lek. | 11:15–12:00
B35: 🗂 Admin | C35: ='Do-Vorlage'!$C$8 -> 0 | D35: ='Do-Vorlage'!$D$8 -> 0
B36: 🎯 Lernziele
B37: 🚀 Einstieg
B38: 📝 Aufgaben / Erarbeitung / Vertiefung / Üben
B39: 🔒 Abschluss / Ergebnissicherung
A41: ── MITTAGSPAUSE
A42: =" 6. Lek. | "&'Do-Vorlage'!$B$9 -> 6. Lek. |
B43: 🗂 Admin | C43: ='Do-Vorlage'!$C$9 -> 0 | D43: ='Do-Vorlage'!$D$9 -> 0
B44: 🎯 Lernziele
B45: 🚀 Einstieg
...

Sheet 28.08.2026
A1: TAGESAGENDA – Freitag, 28.08.2026
A2: 📄 PDF exportieren: Datei → Exportieren → Als PDF/XPS | ✏️ Fach/Klasse aus Freitag-Vorlage (gelb) – zum Überschreiben einfach eintippen
A3: Lehrperson:
A4: Zeit | B4: Unterrichtsphase | C4: Fach ▼ | D4: Klasse ▼ | E4: Inhalt / Beschreibung | F4: Materialien | G4: Differenzierung / Notizen
A5: ◀ Zurück zur Übersicht | E5: 📋 Freitag-Vorlage bearbeiten
A6: =" 1. Lek. | "&'Fr-Vorlage'!$B$4 -> 1. Lek. | 07:30–08:15
B7: 🗂 Admin | C7: ='Fr-Vorlage'!$C$4 -> 0 | D7: ='Fr-Vorlage'!$D$4 -> 0
B8: 🎯 Lernziele
B9: 🚀 Einstieg
B10: 📝 Aufgaben / Erarbeitung / Vertiefung / Üben
B11: 🔒 Abschluss / Ergebnissicherung
A13: =" 2. Lek. | "&'Fr-Vorlage'!$B$5 -> 2. Lek. | 08:20–09:05
B14: 🗂 Admin | C14: ='Fr-Vorlage'!$C$5 -> 0 | D14: ='Fr-Vorlage'!$D$5 -> 0
B15: 🎯 Lernziele
B16: 🚀 Einstieg
B17: 📝 Aufgaben / Erarbeitung / Vertiefung / Üben
B18: 🔒 Abschluss / Ergebnissicherung
A20: =" 3. Lek. | "&'Fr-Vorlage'!$B$6 -> 3. Lek. | 09:10–09:55
B21: 🗂 Admin | C21: ='Fr-Vorlage'!$C$6 -> 0 | D21: ='Fr-Vorlage'!$D$6 -> 0
B22: 🎯 Lernziele
B23: 🚀 Einstieg
B24: 📝 Aufgaben / Erarbeitung / Vertiefung / Üben
B25: 🔒 Abschluss / Ergebnissicherung
A27: =" 4. Lek. | "&'Fr-Vorlage'!$B$7 -> 4. Lek. | 10:25–11:10
B28: 🗂 Admin | C28: ='Fr-Vorlage'!$C$7 -> 0 | D28: ='Fr-Vorlage'!$D$7 -> 0
B29: 🎯 Lernziele
B30: 🚀 Einstieg
B31: 📝 Aufgaben / Erarbeitung / Vertiefung / Üben
B32: 🔒 Abschluss / Ergebnissicherung
A34: =" 5. Lek. | "&'Fr-Vorlage'!$B$8 -> 5. Lek. | 11:15–12:00
B35: 🗂 Admin | C35: ='Fr-Vorlage'!$C$8 -> 0 | D35: ='Fr-Vorlage'!$D$8 -> 0
B36: 🎯 Lernziele
B37: 🚀 Einstieg
B38: 📝 Aufgaben / Erarbeitung / Vertiefung / Üben
B39: 🔒 Abschluss / Ergebnissicherung
A41: ── MITTAGSPAUSE
A42: =" 6. Lek. | "&'Fr-Vorlage'!$B$9 -> 6. Lek. |
B43: 🗂 Admin | C43: ='Fr-Vorlage'!$C$9 -> 0 | D43: ='Fr-Vorlage'!$D$9 -> 0
B44: 🎯 Lernziele
B45: 🚀 Einstieg
...

Sheet 31.08.2026
A1: TAGESAGENDA – Montag, 31.08.2026
A2: 📄 PDF exportieren: Datei → Exportieren → Als PDF/XPS | ✏️ Fach/Klasse aus Montag-Vorlage (gelb) – zum Überschreiben einfach eintippen
A3: Lehrperson:
A4: Zeit | B4: Unterrichtsphase | C4: Fach ▼ | D4: Klasse ▼ | E4: Inhalt / Beschreibung | F4: Materialien | G4: Differenzierung / Notizen
A5: ◀ Zurück zur Übersicht | E5: 📋 Montag-Vorlage bearbeiten
A6: =" 1. Lek. | "&'Mo-Vorlage'!$B$4 -> 1. Lek. | 07:30–08:15
B7: 🗂 Admin | C7: ='Mo-Vorlage'!$C$4 -> 0 | D7: ='Mo-Vorlage'!$D$4 -> 0
B8: 🎯 Lernziele
B9: 🚀 Einstieg
B10: 📝 Aufgaben / Erarbeitung / Vertiefung / Üben
B11: 🔒 Abschluss / Ergebnissicherung
A13: =" 2. Lek. | "&'Mo-Vorlage'!$B$5 -> 2. Lek. | 08:20–09:05
B14: 🗂 Admin | C14: ='Mo-Vorlage'!$C$5 -> 0 | D14: ='Mo-Vorlage'!$D$5 -> 0
B15: 🎯 Lernziele
B16: 🚀 Einstieg
B17: 📝 Aufgaben / Erarbeitung / Vertiefung / Üben
B18: 🔒 Abschluss / Ergebnissicherung
A20: =" 3. Lek. | "&'Mo-Vorlage'!$B$6 -> 3. Lek. | 09:10–09:55
B21: 🗂 Admin | C21: ='Mo-Vorlage'!$C$6 -> 0 | D21: ='Mo-Vorlage'!$D$6 -> 0
B22: 🎯 Lernziele
B23: 🚀 Einstieg
B24: 📝 Aufgaben / Erarbeitung / Vertiefung / Üben
B25: 🔒 Abschluss / Ergebnissicherung
A27: =" 4. Lek. | "&'Mo-Vorlage'!$B$7 -> 4. Lek. | 10:25–11:10
B28: 🗂 Admin | C28: ='Mo-Vorlage'!$C$7 -> 0 | D28: ='Mo-Vorlage'!$D$7 -> 0
B29: 🎯 Lernziele
B30: 🚀 Einstieg
B31: 📝 Aufgaben / Erarbeitung / Vertiefung / Üben
B32: 🔒 Abschluss / Ergebnissicherung
A34: =" 5. Lek. | "&'Mo-Vorlage'!$B$8 -> 5. Lek. | 11:15–12:00
B35: 🗂 Admin | C35: ='Mo-Vorlage'!$C$8 -> 0 | D35: ='Mo-Vorlage'!$D$8 -> 0
B36: 🎯 Lernziele
B37: 🚀 Einstieg
B38: 📝 Aufgaben / Erarbeitung / Vertiefung / Üben
B39: 🔒 Abschluss / Ergebnissicherung
A41: ── MITTAGSPAUSE
A42: =" 6. Lek. | "&'Mo-Vorlage'!$B$9 -> 6. Lek. |
B43: 🗂 Admin | C43: ='Mo-Vorlage'!$C$9 -> 0 | D43: ='Mo-Vorlage'!$D$9 -> 0
B44: 🎯 Lernziele
B45: 🚀 Einstieg
...

Sheet 01.09.2026
A1: TAGESAGENDA – Dienstag, 01.09.2026
A2: 📄 PDF exportieren: Datei → Exportieren → Als PDF/XPS | ✏️ Fach/Klasse aus Dienstag-Vorlage (gelb) – zum Überschreiben einfach eintippen
A3: Lehrperson:
A4: Zeit | B4: Unterrichtsphase | C4: Fach ▼ | D4: Klasse ▼ | E4: Inhalt / Beschreibung | F4: Materialien | G4: Differenzierung / Notizen
A5: ◀ Zurück zur Übersicht | E5: 📋 Dienstag-Vorlage bearbeiten
A6: =" 1. Lek. | "&'Di-Vorlage'!$B$4 -> 1. Lek. | 07:30–08:15
B7: 🗂 Admin | C7: ='Di-Vorlage'!$C$4 -> 0 | D7: ='Di-Vorlage'!$D$4 -> 0
B8: 🎯 Lernziele
B9: 🚀 Einstieg
B10: 📝 Aufgaben / Erarbeitung / Vertiefung / Üben
B11: 🔒 Abschluss / Ergebnissicherung
A13: =" 2. Lek. | "&'Di-Vorlage'!$B$5 -> 2. Lek. | 08:20–09:05
B14: 🗂 Admin | C14: ='Di-Vorlage'!$C$5 -> 0 | D14: ='Di-Vorlage'!$D$5 -> 0
B15: 🎯 Lernziele
B16: 🚀 Einstieg
B17: 📝 Aufgaben / Erarbeitung / Vertiefung / Üben
B18: 🔒 Abschluss / Ergebnissicherung
A20: =" 3. Lek. | "&'Di-Vorlage'!$B$6 -> 3. Lek. | 09:10–09:55
B21: 🗂 Admin | C21: ='Di-Vorlage'!$C$6 -> 0 | D21: ='Di-Vorlage'!$D$6 -> 0
B22: 🎯 Lernziele
B23: 🚀 Einstieg
B24: 📝 Aufgaben / Erarbeitung / Vertiefung / Üben
B25: 🔒 Abschluss / Ergebnissicherung
A27: =" 4. Lek. | "&'Di-Vorlage'!$B$7 -> 4. Lek. | 10:25–11:10
B28: 🗂 Admin | C28: ='Di-Vorlage'!$C$7 -> 0 | D28: ='Di-Vorlage'!$D$7 -> 0
B29: 🎯 Lernziele
B30: 🚀 Einstieg
B31: 📝 Aufgaben / Erarbeitung / Vertiefung / Üben
B32: 🔒 Abschluss / Ergebnissicherung
A34: =" 5. Lek. | "&'Di-Vorlage'!$B$8 -> 5. Lek. | 11:15–12:00
B35: 🗂 Admin | C35: ='Di-Vorlage'!$C$8 -> 0 | D35: ='Di-Vorlage'!$D$8 -> 0
B36: 🎯 Lernziele
B37: 🚀 Einstieg
B38: 📝 Aufgaben / Erarbeitung / Vertiefung / Üben
B39: 🔒 Abschluss / Ergebnissicherung
A41: ── MITTAGSPAUSE
A42: =" 6. Lek. | "&'Di-Vorlage'!$B$9 -> 6. Lek. |
B43: 🗂 Admin | C43: ='Di-Vorlage'!$C$9 -> 0 | D43: ='Di-Vorlage'!$D$9 -> 0
B44: 🎯 Lernziele
B45: 🚀 Einstieg
...

Sheet 02.09.2026
A1: TAGESAGENDA – Mittwoch, 02.09.2026
A2: 📄 PDF exportieren: Datei → Exportieren → Als PDF/XPS | ✏️ Fach/Klasse aus Mittwoch-Vorlage (gelb) – zum Überschreiben einfach eintippen
A3: Lehrperson:
A4: Zeit | B4: Unterrichtsphase | C4: Fach ▼ | D4: Klasse ▼ | E4: Inhalt / Beschreibung | F4: Materialien | G4: Differenzierung / Notizen
A5: ◀ Zurück zur Übersicht | E5: 📋 Mittwoch-Vorlage bearbeiten
A6: =" 1. Lek. | "&'Mi-Vorlage'!$B$4 -> 1. Lek. | 07:30–08:15
B7: 🗂 Admin | C7: ='Mi-Vorlage'!$C$4 -> 0 | D7: ='Mi-Vorlage'!$D$4 -> 0
B8: 🎯 Lernziele
B9: 🚀 Einstieg
B10: 📝 Aufgaben / Erarbeitung / Vertiefung / Üben
B11: 🔒 Abschluss / Ergebnissicherung
A13: =" 2. Lek. | "&'Mi-Vorlage'!$B$5 -> 2. Lek. | 08:20–09:05
B14: 🗂 Admin | C14: ='Mi-Vorlage'!$C$5 -> 0 | D14: ='Mi-Vorlage'!$D$5 -> 0
B15: 🎯 Lernziele
B16: 🚀 Einstieg
B17: 📝 Aufgaben / Erarbeitung / Vertiefung / Üben
B18: 🔒 Abschluss / Ergebnissicherung
A20: =" 3. Lek. | "&'Mi-Vorlage'!$B$6 -> 3. Lek. | 09:10–09:55
B21: 🗂 Admin | C21: ='Mi-Vorlage'!$C$6 -> 0 | D21: ='Mi-Vorlage'!$D$6 -> 0
B22: 🎯 Lernziele
B23: 🚀 Einstieg
B24: 📝 Aufgaben / Erarbeitung / Vertiefung / Üben
B25: 🔒 Abschluss / Ergebnissicherung
A27: =" 4. Lek. | "&'Mi-Vorlage'!$B$7 -> 4. Lek. | 10:25–11:10
B28: 🗂 Admin | C28: ='Mi-Vorlage'!$C$7 -> 0 | D28: ='Mi-Vorlage'!$D$7 -> 0
B29: 🎯 Lernziele
B30: 🚀 Einstieg
B31: 📝 Aufgaben / Erarbeitung / Vertiefung / Üben
B32: 🔒 Abschluss / Ergebnissicherung
A34: =" 5. Lek. | "&'Mi-Vorlage'!$B$8 -> 5. Lek. | 11:15–12:00
B35: 🗂 Admin | C35: ='Mi-Vorlage'!$C$8 -> 0 | D35: ='Mi-Vorlage'!$D$8 -> 0
B36: 🎯 Lernziele
B37: 🚀 Einstieg
B38: 📝 Aufgaben / Erarbeitung / Vertiefung / Üben
B39: 🔒 Abschluss / Ergebnissicherung
A41: ── MITTAGSPAUSE
A42: =" 6. Lek. | "&'Mi-Vorlage'!$B$9 -> 6. Lek. |
B43: 🗂 Admin | C43: ='Mi-Vorlage'!$C$9 -> 0 | D43: ='Mi-Vorlage'!$D$9 -> 0
B44: 🎯 Lernziele
B45: 🚀 Einstieg
...

Sheet 03.09.2026
A1: TAGESAGENDA – Donnerstag, 03.09.2026
A2: 📄 PDF exportieren: Datei → Exportieren → Als PDF/XPS | ✏️ Fach/Klasse aus Donnerstag-Vorlage (gelb) – zum Überschreiben einfach eintippen
A3: Lehrperson:
A4: Zeit | B4: Unterrichtsphase | C4: Fach ▼ | D4: Klasse ▼ | E4: Inhalt / Beschreibung | F4: Materialien | G4: Differenzierung / Notizen
A5: ◀ Zurück zur Übersicht | E5: 📋 Donnerstag-Vorlage bearbeiten
A6: =" 1. Lek. | "&'Do-Vorlage'!$B$4 -> 1. Lek. | 07:30–08:15
B7: 🗂 Admin | C7: ='Do-Vorlage'!$C$4 -> 0 | D7: ='Do-Vorlage'!$D$4 -> 0
B8: 🎯 Lernziele
B9: 🚀 Einstieg
B10: 📝 Aufgaben / Erarbeitung / Vertiefung / Üben
B11: 🔒 Abschluss / Ergebnissicherung
A13: =" 2. Lek. | "&'Do-Vorlage'!$B$5 -> 2. Lek. | 08:20–09:05
B14: 🗂 Admin | C14: ='Do-Vorlage'!$C$5 -> 0 | D14: ='Do-Vorlage'!$D$5 -> 0
B15: 🎯 Lernziele
B16: 🚀 Einstieg
B17: 📝 Aufgaben / Erarbeitung / Vertiefung / Üben
B18: 🔒 Abschluss / Ergebnissicherung
A20: =" 3. Lek. | "&'Do-Vorlage'!$B$6 -> 3. Lek. | 09:10–09:55
B21: 🗂 Admin | C21: ='Do-Vorlage'!$C$6 -> 0 | D21: ='Do-Vorlage'!$D$6 -> 0
B22: 🎯 Lernziele
B23: 🚀 Einstieg
B24: 📝 Aufgaben / Erarbeitung / Vertiefung / Üben
B25: 🔒 Abschluss / Ergebnissicherung
A27: =" 4. Lek. | "&'Do-Vorlage'!$B$7 -> 4. Lek. | 10:25–11:10
B28: 🗂 Admin | C28: ='Do-Vorlage'!$C$7 -> 0 | D28: ='Do-Vorlage'!$D$7 -> 0
B29: 🎯 Lernziele
B30: 🚀 Einstieg
B31: 📝 Aufgaben / Erarbeitung / Vertiefung / Üben
B32: 🔒 Abschluss / Ergebnissicherung
A34: =" 5. Lek. | "&'Do-Vorlage'!$B$8 -> 5. Lek. | 11:15–12:00
B35: 🗂 Admin | C35: ='Do-Vorlage'!$C$8 -> 0 | D35: ='Do-Vorlage'!$D$8 -> 0
B36: 🎯 Lernziele
B37: 🚀 Einstieg
B38: 📝 Aufgaben / Erarbeitung / Vertiefung / Üben
B39: 🔒 Abschluss / Ergebnissicherung
A41: ── MITTAGSPAUSE
A42: =" 6. Lek. | "&'Do-Vorlage'!$B$9 -> 6. Lek. |
B43: 🗂 Admin | C43: ='Do-Vorlage'!$C$9 -> 0 | D43: ='Do-Vorlage'!$D$9 -> 0
B44: 🎯 Lernziele
B45: 🚀 Einstieg
...

Sheet 04.09.2026
A1: TAGESAGENDA – Freitag, 04.09.2026
A2: 📄 PDF exportieren: Datei → Exportieren → Als PDF/XPS | ✏️ Fach/Klasse aus Freitag-Vorlage (gelb) – zum Überschreiben einfach eintippen
A3: Lehrperson:
A4: Zeit | B4: Unterrichtsphase | C4: Fach ▼ | D4: Klasse ▼ | E4: Inhalt / Beschreibung | F4: Materialien | G4: Differenzierung / Notizen
A5: ◀ Zurück zur Übersicht | E5: 📋 Freitag-Vorlage bearbeiten
A6: =" 1. Lek. | "&'Fr-Vorlage'!$B$4 -> 1. Lek. | 07:30–08:15
B7: 🗂 Admin | C7: ='Fr-Vorlage'!$C$4 -> 0 | D7: ='Fr-Vorlage'!$D$4 -> 0
B8: 🎯 Lernziele
B9: 🚀 Einstieg
B10: 📝 Aufgaben / Erarbeitung / Vertiefung / Üben
B11: 🔒 Abschluss / Ergebnissicherung
A13: =" 2. Lek. | "&'Fr-Vorlage'!$B$5 -> 2. Lek. | 08:20–09:05
B14: 🗂 Admin | C14: ='Fr-Vorlage'!$C$5 -> 0 | D14: ='Fr-Vorlage'!$D$5 -> 0
B15: 🎯 Lernziele
B16: 🚀 Einstieg
B17: 📝 Aufgaben / Erarbeitung / Vertiefung / Üben
B18: 🔒 Abschluss / Ergebnissicherung
A20: =" 3. Lek. | "&'Fr-Vorlage'!$B$6 -> 3. Lek. | 09:10–09:55
B21: 🗂 Admin | C21: ='Fr-Vorlage'!$C$6 -> 0 | D21: ='Fr-Vorlage'!$D$6 -> 0
B22: 🎯 Lernziele
B23: 🚀 Einstieg
B24: 📝 Aufgaben / Erarbeitung / Vertiefung / Üben
B25: 🔒 Abschluss / Ergebnissicherung
A27: =" 4. Lek. | "&'Fr-Vorlage'!$B$7 -> 4. Lek. | 10:25–11:10
B28: 🗂 Admin | C28: ='Fr-Vorlage'!$C$7 -> 0 | D28: ='Fr-Vorlage'!$D$7 -> 0
B29: 🎯 Lernziele
B30: 🚀 Einstieg
B31: 📝 Aufgaben / Erarbeitung / Vertiefung / Üben
B32: 🔒 Abschluss / Ergebnissicherung
A34: =" 5. Lek. | "&'Fr-Vorlage'!$B$8 -> 5. Lek. | 11:15–12:00
B35: 🗂 Admin | C35: ='Fr-Vorlage'!$C$8 -> 0 | D35: ='Fr-Vorlage'!$D$8 -> 0
B36: 🎯 Lernziele
B37: 🚀 Einstieg
B38: 📝 Aufgaben / Erarbeitung / Vertiefung / Üben
B39: 🔒 Abschluss / Ergebnissicherung
A41: ── MITTAGSPAUSE
A42: =" 6. Lek. | "&'Fr-Vorlage'!$B$9 -> 6. Lek. |
B43: 🗂 Admin | C43: ='Fr-Vorlage'!$C$9 -> 0 | D43: ='Fr-Vorlage'!$D$9 -> 0
B44: 🎯 Lernziele
B45: 🚀 Einstieg
...

Sheet 07.09.2026
A1: TAGESAGENDA – Montag, 07.09.2026
A2: 📄 PDF exportieren: Datei → Exportieren → Als PDF/XPS | ✏️ Fach/Klasse aus Montag-Vorlage (gelb) – zum Überschreiben einfach eintippen
A3: Lehrperson:
A4: Zeit | B4: Unterrichtsphase | C4: Fach ▼ | D4: Klasse ▼ | E4: Inhalt / Beschreibung | F4: Materialien | G4: Differenzierung / Notizen
A5: ◀ Zurück zur Übersicht | E5: 📋 Montag-Vorlage bearbeiten
A6: =" 1. Lek. | "&'Mo-Vorlage'!$B$4 -> 1. Lek. | 07:30–08:15
B7: 🗂 Admin | C7: ='Mo-Vorlage'!$C$4 -> 0 | D7: ='Mo-Vorlage'!$D$4 -> 0
B8: 🎯 Lernziele
B9: 🚀 Einstieg
B10: 📝 Aufgaben / Erarbeitung / Vertiefung / Üben
B11: 🔒 Abschluss / Ergebnissicherung
A13: =" 2. Lek. | "&'Mo-Vorlage'!$B$5 -> 2. Lek. | 08:20–09:05
B14: 🗂 Admin | C14: ='Mo-Vorlage'!$C$5 -> 0 | D14: ='Mo-Vorlage'!$D$5 -> 0
B15: 🎯 Lernziele
B16: 🚀 Einstieg
B17: 📝 Aufgaben / Erarbeitung / Vertiefung / Üben
B18: 🔒 Abschluss / Ergebnissicherung
A20: =" 3. Lek. | "&'Mo-Vorlage'!$B$6 -> 3. Lek. | 09:10–09:55
B21: 🗂 Admin | C21: ='Mo-Vorlage'!$C$6 -> 0 | D21: ='Mo-Vorlage'!$D$6 -> 0
B22: 🎯 Lernziele
B23: 🚀 Einstieg
B24: 📝 Aufgaben / Erarbeitung / Vertiefung / Üben
B25: 🔒 Abschluss / Ergebnissicherung
A27: =" 4. Lek. | "&'Mo-Vorlage'!$B$7 -> 4. Lek. | 10:25–11:10
B28: 🗂 Admin | C28: ='Mo-Vorlage'!$C$7 -> 0 | D28: ='Mo-Vorlage'!$D$7 -> 0
B29: 🎯 Lernziele
B30: 🚀 Einstieg
B31: 📝 Aufgaben / Erarbeitung / Vertiefung / Üben
B32: 🔒 Abschluss / Ergebnissicherung
A34: =" 5. Lek. | "&'Mo-Vorlage'!$B$8 -> 5. Lek. | 11:15–12:00
B35: 🗂 Admin | C35: ='Mo-Vorlage'!$C$8 -> 0 | D35: ='Mo-Vorlage'!$D$8 -> 0
B36: 🎯 Lernziele
B37: 🚀 Einstieg
B38: 📝 Aufgaben / Erarbeitung / Vertiefung / Üben
B39: 🔒 Abschluss / Ergebnissicherung
A41: ── MITTAGSPAUSE
A42: =" 6. Lek. | "&'Mo-Vorlage'!$B$9 -> 6. Lek. |
B43: 🗂 Admin | C43: ='Mo-Vorlage'!$C$9 -> 0 | D43: ='Mo-Vorlage'!$D$9 -> 0
B44: 🎯 Lernziele
B45: 🚀 Einstieg
...

Sheet 08.09.2026
A1: TAGESAGENDA – Dienstag, 08.09.2026
A2: 📄 PDF exportieren: Datei → Exportieren → Als PDF/XPS | ✏️ Fach/Klasse aus Dienstag-Vorlage (gelb) – zum Überschreiben einfach eintippen
A3: Lehrperson:
A4: Zeit | B4: Unterrichtsphase | C4: Fach ▼ | D4: Klasse ▼ | E4: Inhalt / Beschreibung | F4: Materialien | G4: Differenzierung / Notizen
A5: ◀ Zurück zur Übersicht | E5: 📋 Dienstag-Vorlage bearbeiten
A6: =" 1. Lek. | "&'Di-Vorlage'!$B$4 -> 1. Lek. | 07:30–08:15
B7: 🗂 Admin | C7: ='Di-Vorlage'!$C$4 -> 0 | D7: ='Di-Vorlage'!$D$4 -> 0
B8: 🎯 Lernziele
B9: 🚀 Einstieg
B10: 📝 Aufgaben / Erarbeitung / Vertiefung / Üben
B11: 🔒 Abschluss / Ergebnissicherung
A13: =" 2. Lek. | "&'Di-Vorlage'!$B$5 -> 2. Lek. | 08:20–09:05
B14: 🗂 Admin | C14: ='Di-Vorlage'!$C$5 -> 0 | D14: ='Di-Vorlage'!$D$5 -> 0
B15: 🎯 Lernziele
B16: 🚀 Einstieg
B17: 📝 Aufgaben / Erarbeitung / Vertiefung / Üben
B18: 🔒 Abschluss / Ergebnissicherung
A20: =" 3. Lek. | "&'Di-Vorlage'!$B$6 -> 3. Lek. | 09:10–09:55
B21: 🗂 Admin | C21: ='Di-Vorlage'!$C$6 -> 0 | D21: ='Di-Vorlage'!$D$6 -> 0
B22: 🎯 Lernziele
B23: 🚀 Einstieg
B24: 📝 Aufgaben / Erarbeitung / Vertiefung / Üben
B25: 🔒 Abschluss / Ergebnissicherung
A27: =" 4. Lek. | "&'Di-Vorlage'!$B$7 -> 4. Lek. | 10:25–11:10
B28: 🗂 Admin | C28: ='Di-Vorlage'!$C$7 -> 0 | D28: ='Di-Vorlage'!$D$7 -> 0
B29: 🎯 Lernziele
B30: 🚀 Einstieg
B31: 📝 Aufgaben / Erarbeitung / Vertiefung / Üben
B32: 🔒 Abschluss / Ergebnissicherung
A34: =" 5. Lek. | "&'Di-Vorlage'!$B$8 -> 5. Lek. | 11:15–12:00
B35: 🗂 Admin | C35: ='Di-Vorlage'!$C$8 -> 0 | D35: ='Di-Vorlage'!$D$8 -> 0
B36: 🎯 Lernziele
B37: 🚀 Einstieg
B38: 📝 Aufgaben / Erarbeitung / Vertiefung / Üben
B39: 🔒 Abschluss / Ergebnissicherung
A41: ── MITTAGSPAUSE
A42: =" 6. Lek. | "&'Di-Vorlage'!$B$9 -> 6. Lek. |
B43: 🗂 Admin | C43: ='Di-Vorlage'!$C$9 -> 0 | D43: ='Di-Vorlage'!$D$9 -> 0
B44: 🎯 Lernziele
B45: 🚀 Einstieg
...

Sheet 09.09.2026
A1: TAGESAGENDA – Mittwoch, 09.09.2026
A2: 📄 PDF exportieren: Datei → Exportieren → Als PDF/XPS | ✏️ Fach/Klasse aus Mittwoch-Vorlage (gelb) – zum Überschreiben einfach eintippen
A3: Lehrperson:
A4: Zeit | B4: Unterrichtsphase | C4: Fach ▼ | D4: Klasse ▼ | E4: Inhalt / Beschreibung | F4: Materialien | G4: Differenzierung / Notizen
A5: ◀ Zurück zur Übersicht | E5: 📋 Mittwoch-Vorlage bearbeiten
A6: =" 1. Lek. | "&'Mi-Vorlage'!$B$4 -> 1. Lek. | 07:30–08:15
B7: 🗂 Admin | C7: ='Mi-Vorlage'!$C$4 -> 0 | D7: ='Mi-Vorlage'!$D$4 -> 0
B8: 🎯 Lernziele
B9: 🚀 Einstieg
B10: 📝 Aufgaben / Erarbeitung / Vertiefung / Üben
B11: 🔒 Abschluss / Ergebnissicherung
A13: =" 2. Lek. | "&'Mi-Vorlage'!$B$5 -> 2. Lek. | 08:20–09:05
B14: 🗂 Admin | C14: ='Mi-Vorlage'!$C$5 -> 0 | D14: ='Mi-Vorlage'!$D$5 -> 0
B15: 🎯 Lernziele
B16: 🚀 Einstieg
B17: 📝 Aufgaben / Erarbeitung / Vertiefung / Üben
B18: 🔒 Abschluss / Ergebnissicherung
A20: =" 3. Lek. | "&'Mi-Vorlage'!$B$6 -> 3. Lek. | 09:10–09:55
B21: 🗂 Admin | C21: ='Mi-Vorlage'!$C$6 -> 0 | D21: ='Mi-Vorlage'!$D$6 -> 0
B22: 🎯 Lernziele
B23: 🚀 Einstieg
B24: 📝 Aufgaben / Erarbeitung / Vertiefung / Üben
B25: 🔒 Abschluss / Ergebnissicherung
A27: =" 4. Lek. | "&'Mi-Vorlage'!$B$7 -> 4. Lek. | 10:25–11:10
B28: 🗂 Admin | C28: ='Mi-Vorlage'!$C$7 -> 0 | D28: ='Mi-Vorlage'!$D$7 -> 0
B29: 🎯 Lernziele
B30: 🚀 Einstieg
B31: 📝 Aufgaben / Erarbeitung / Vertiefung / Üben
B32: 🔒 Abschluss / Ergebnissicherung
A34: =" 5. Lek. | "&'Mi-Vorlage'!$B$8 -> 5. Lek. | 11:15–12:00
B35: 🗂 Admin | C35: ='Mi-Vorlage'!$C$8 -> 0 | D35: ='Mi-Vorlage'!$D$8 -> 0
B36: 🎯 Lernziele
B37: 🚀 Einstieg
B38: 📝 Aufgaben / Erarbeitung / Vertiefung / Üben
B39: 🔒 Abschluss / Ergebnissicherung
A41: ── MITTAGSPAUSE
A42: =" 6. Lek. | "&'Mi-Vorlage'!$B$9 -> 6. Lek. |
B43: 🗂 Admin | C43: ='Mi-Vorlage'!$C$9 -> 0 | D43: ='Mi-Vorlage'!$D$9 -> 0
B44: 🎯 Lernziele
B45: 🚀 Einstieg
...

Sheet 10.09.2026
A1: TAGESAGENDA – Donnerstag, 10.09.2026
A2: 📄 PDF exportieren: Datei → Exportieren → Als PDF/XPS | ✏️ Fach/Klasse aus Donnerstag-Vorlage (gelb) – zum Überschreiben einfach eintippen
A3: Lehrperson:
A4: Zeit | B4: Unterrichtsphase | C4: Fach ▼ | D4: Klasse ▼ | E4: Inhalt / Beschreibung | F4: Materialien | G4: Differenzierung / Notizen
A5: ◀ Zurück zur Übersicht | E5: 📋 Donnerstag-Vorlage bearbeiten
A6: =" 1. Lek. | "&'Do-Vorlage'!$B$4 -> 1. Lek. | 07:30–08:15
B7: 🗂 Admin | C7: ='Do-Vorlage'!$C$4 -> 0 | D7: ='Do-Vorlage'!$D$4 -> 0
B8: 🎯 Lernziele
B9: 🚀 Einstieg
B10: 📝 Aufgaben / Erarbeitung / Vertiefung / Üben
B11: 🔒 Abschluss / Ergebnissicherung
A13: =" 2. Lek. | "&'Do-Vorlage'!$B$5 -> 2. Lek. | 08:20–09:05
B14: 🗂 Admin | C14: ='Do-Vorlage'!$C$5 -> 0 | D14: ='Do-Vorlage'!$D$5 -> 0
B15: 🎯 Lernziele
B16: 🚀 Einstieg
B17: 📝 Aufgaben / Erarbeitung / Vertiefung / Üben
B18: 🔒 Abschluss / Ergebnissicherung
A20: =" 3. Lek. | "&'Do-Vorlage'!$B$6 -> 3. Lek. | 09:10–09:55
B21: 🗂 Admin | C21: ='Do-Vorlage'!$C$6 -> 0 | D21: ='Do-Vorlage'!$D$6 -> 0
B22: 🎯 Lernziele
B23: 🚀 Einstieg
B24: 📝 Aufgaben / Erarbeitung / Vertiefung / Üben
B25: 🔒 Abschluss / Ergebnissicherung
A27: =" 4. Lek. | "&'Do-Vorlage'!$B$7 -> 4. Lek. | 10:25–11:10
B28: 🗂 Admin | C28: ='Do-Vorlage'!$C$7 -> 0 | D28: ='Do-Vorlage'!$D$7 -> 0
B29: 🎯 Lernziele
B30: 🚀 Einstieg
B31: 📝 Aufgaben / Erarbeitung / Vertiefung / Üben
B32: 🔒 Abschluss / Ergebnissicherung
A34: =" 5. Lek. | "&'Do-Vorlage'!$B$8 -> 5. Lek. | 11:15–12:00
B35: 🗂 Admin | C35: ='Do-Vorlage'!$C$8 -> 0 | D35: ='Do-Vorlage'!$D$8 -> 0
B36: 🎯 Lernziele
B37: 🚀 Einstieg
B38: 📝 Aufgaben / Erarbeitung / Vertiefung / Üben
B39: 🔒 Abschluss / Ergebnissicherung
A41: ── MITTAGSPAUSE
A42: =" 6. Lek. | "&'Do-Vorlage'!$B$9 -> 6. Lek. |
B43: 🗂 Admin | C43: ='Do-Vorlage'!$C$9 -> 0 | D43: ='Do-Vorlage'!$D$9 -> 0
B44: 🎯 Lernziele
B45: 🚀 Einstieg
...

Sheet 11.09.2026
A1: TAGESAGENDA – Freitag, 11.09.2026
A2: 📄 PDF exportieren: Datei → Exportieren → Als PDF/XPS | ✏️ Fach/Klasse aus Freitag-Vorlage (gelb) – zum Überschreiben einfach eintippen
A3: Lehrperson:
A4: Zeit | B4: Unterrichtsphase | C4: Fach ▼ | D4: Klasse ▼ | E4: Inhalt / Beschreibung | F4: Materialien | G4: Differenzierung / Notizen
A5: ◀ Zurück zur Übersicht | E5: 📋 Freitag-Vorlage bearbeiten
A6: =" 1. Lek. | "&'Fr-Vorlage'!$B$4 -> 1. Lek. | 07:30–08:15
B7: 🗂 Admin | C7: ='Fr-Vorlage'!$C$4 -> 0 | D7: ='Fr-Vorlage'!$D$4 -> 0
B8: 🎯 Lernziele
B9: 🚀 Einstieg
B10: 📝 Aufgaben / Erarbeitung / Vertiefung / Üben
B11: 🔒 Abschluss / Ergebnissicherung
A13: =" 2. Lek. | "&'Fr-Vorlage'!$B$5 -> 2. Lek. | 08:20–09:05
B14: 🗂 Admin | C14: ='Fr-Vorlage'!$C$5 -> 0 | D14: ='Fr-Vorlage'!$D$5 -> 0
B15: 🎯 Lernziele
B16: 🚀 Einstieg
B17: 📝 Aufgaben / Erarbeitung / Vertiefung / Üben
B18: 🔒 Abschluss / Ergebnissicherung
A20: =" 3. Lek. | "&'Fr-Vorlage'!$B$6 -> 3. Lek. | 09:10–09:55
B21: 🗂 Admin | C21: ='Fr-Vorlage'!$C$6 -> 0 | D21: ='Fr-Vorlage'!$D$6 -> 0
B22: 🎯 Lernziele
B23: 🚀 Einstieg
B24: 📝 Aufgaben / Erarbeitung / Vertiefung / Üben
B25: 🔒 Abschluss / Ergebnissicherung
A27: =" 4. Lek. | "&'Fr-Vorlage'!$B$7 -> 4. Lek. | 10:25–11:10
B28: 🗂 Admin | C28: ='Fr-Vorlage'!$C$7 -> 0 | D28: ='Fr-Vorlage'!$D$7 -> 0
B29: 🎯 Lernziele
B30: 🚀 Einstieg
B31: 📝 Aufgaben / Erarbeitung / Vertiefung / Üben
B32: 🔒 Abschluss / Ergebnissicherung
A34: =" 5. Lek. | "&'Fr-Vorlage'!$B$8 -> 5. Lek. | 11:15–12:00
B35: 🗂 Admin | C35: ='Fr-Vorlage'!$C$8 -> 0 | D35: ='Fr-Vorlage'!$D$8 -> 0
B36: 🎯 Lernziele
B37: 🚀 Einstieg
B38: 📝 Aufgaben / Erarbeitung / Vertiefung / Üben
B39: 🔒 Abschluss / Ergebnissicherung
A41: ── MITTAGSPAUSE
A42: =" 6. Lek. | "&'Fr-Vorlage'!$B$9 -> 6. Lek. |
B43: 🗂 Admin | C43: ='Fr-Vorlage'!$C$9 -> 0 | D43: ='Fr-Vorlage'!$D$9 -> 0
B44: 🎯 Lernziele
B45: 🚀 Einstieg
...

Sheet 14.09.2026
A1: TAGESAGENDA – Montag, 14.09.2026
A2: 📄 PDF exportieren: Datei → Exportieren → Als PDF/XPS | ✏️ Fach/Klasse aus Montag-Vorlage (gelb) – zum Überschreiben einfach eintippen
A3: Lehrperson:
A4: Zeit | B4: Unterrichtsphase | C4: Fach ▼ | D4: Klasse ▼ | E4: Inhalt / Beschreibung | F4: Materialien | G4: Differenzierung / Notizen
A5: ◀ Zurück zur Übersicht | E5: 📋 Montag-Vorlage bearbeiten
A6: =" 1. Lek. | "&'Mo-Vorlage'!$B$4 -> 1. Lek. | 07:30–08:15
B7: 🗂 Admin | C7: ='Mo-Vorlage'!$C$4 -> 0 | D7: ='Mo-Vorlage'!$D$4 -> 0
B8: 🎯 Lernziele
B9: 🚀 Einstieg
B10: 📝 Aufgaben / Erarbeitung / Vertiefung / Üben
B11: 🔒 Abschluss / Ergebnissicherung
A13: =" 2. Lek. | "&'Mo-Vorlage'!$B$5 -> 2. Lek. | 08:20–09:05
B14: 🗂 Admin | C14: ='Mo-Vorlage'!$C$5 -> 0 | D14: ='Mo-Vorlage'!$D$5 -> 0
B15: 🎯 Lernziele
B16: 🚀 Einstieg
B17: 📝 Aufgaben / Erarbeitung / Vertiefung / Üben
B18: 🔒 Abschluss / Ergebnissicherung
A20: =" 3. Lek. | "&'Mo-Vorlage'!$B$6 -> 3. Lek. | 09:10–09:55
B21: 🗂 Admin | C21: ='Mo-Vorlage'!$C$6 -> 0 | D21: ='Mo-Vorlage'!$D$6 -> 0
B22: 🎯 Lernziele
B23: 🚀 Einstieg
B24: 📝 Aufgaben / Erarbeitung / Vertiefung / Üben
B25: 🔒 Abschluss / Ergebnissicherung
A27: =" 4. Lek. | "&'Mo-Vorlage'!$B$7 -> 4. Lek. | 10:25–11:10
B28: 🗂 Admin | C28: ='Mo-Vorlage'!$C$7 -> 0 | D28: ='Mo-Vorlage'!$D$7 -> 0
B29: 🎯 Lernziele
B30: 🚀 Einstieg
B31: 📝 Aufgaben / Erarbeitung / Vertiefung / Üben
B32: 🔒 Abschluss / Ergebnissicherung
A34: =" 5. Lek. | "&'Mo-Vorlage'!$B$8 -> 5. Lek. | 11:15–12:00
B35: 🗂 Admin | C35: ='Mo-Vorlage'!$C$8 -> 0 | D35: ='Mo-Vorlage'!$D$8 -> 0
B36: 🎯 Lernziele
B37: 🚀 Einstieg
B38: 📝 Aufgaben / Erarbeitung / Vertiefung / Üben
B39: 🔒 Abschluss / Ergebnissicherung
A41: ── MITTAGSPAUSE
A42: =" 6. Lek. | "&'Mo-Vorlage'!$B$9 -> 6. Lek. |
B43: 🗂 Admin | C43: ='Mo-Vorlage'!$C$9 -> 0 | D43: ='Mo-Vorlage'!$D$9 -> 0
B44: 🎯 Lernziele
B45: 🚀 Einstieg
...

Sheet 15.09.2026
A1: TAGESAGENDA – Dienstag, 15.09.2026
A2: 📄 PDF exportieren: Datei → Exportieren → Als PDF/XPS | ✏️ Fach/Klasse aus Dienstag-Vorlage (gelb) – zum Überschreiben einfach eintippen
A3: Lehrperson:
A4: Zeit | B4: Unterrichtsphase | C4: Fach ▼ | D4: Klasse ▼ | E4: Inhalt / Beschreibung | F4: Materialien | G4: Differenzierung / Notizen
A5: ◀ Zurück zur Übersicht | E5: 📋 Dienstag-Vorlage bearbeiten
A6: =" 1. Lek. | "&'Di-Vorlage'!$B$4 -> 1. Lek. | 07:30–08:15
B7: 🗂 Admin | C7: ='Di-Vorlage'!$C$4 -> 0 | D7: ='Di-Vorlage'!$D$4 -> 0
B8: 🎯 Lernziele
B9: 🚀 Einstieg
B10: 📝 Aufgaben / Erarbeitung / Vertiefung / Üben
B11: 🔒 Abschluss / Ergebnissicherung
A13: =" 2. Lek. | "&'Di-Vorlage'!$B$5 -> 2. Lek. | 08:20–09:05
B14: 🗂 Admin | C14: ='Di-Vorlage'!$C$5 -> 0 | D14: ='Di-Vorlage'!$D$5 -> 0
B15: 🎯 Lernziele
B16: 🚀 Einstieg
B17: 📝 Aufgaben / Erarbeitung / Vertiefung / Üben
B18: 🔒 Abschluss / Ergebnissicherung
A20: =" 3. Lek. | "&'Di-Vorlage'!$B$6 -> 3. Lek. | 09:10–09:55
B21: 🗂 Admin | C21: ='Di-Vorlage'!$C$6 -> 0 | D21: ='Di-Vorlage'!$D$6 -> 0
B22: 🎯 Lernziele
B23: 🚀 Einstieg
B24: 📝 Aufgaben / Erarbeitung / Vertiefung / Üben
B25: 🔒 Abschluss / Ergebnissicherung
A27: =" 4. Lek. | "&'Di-Vorlage'!$B$7 -> 4. Lek. | 10:25–11:10
B28: 🗂 Admin | C28: ='Di-Vorlage'!$C$7 -> 0 | D28: ='Di-Vorlage'!$D$7 -> 0
B29: 🎯 Lernziele
B30: 🚀 Einstieg
B31: 📝 Aufgaben / Erarbeitung / Vertiefung / Üben
B32: 🔒 Abschluss / Ergebnissicherung
A34: =" 5. Lek. | "&'Di-Vorlage'!$B$8 -> 5. Lek. | 11:15–12:00
B35: 🗂 Admin | C35: ='Di-Vorlage'!$C$8 -> 0 | D35: ='Di-Vorlage'!$D$8 -> 0
B36: 🎯 Lernziele
B37: 🚀 Einstieg
B38: 📝 Aufgaben / Erarbeitung / Vertiefung / Üben
B39: 🔒 Abschluss / Ergebnissicherung
A41: ── MITTAGSPAUSE
A42: =" 6. Lek. | "&'Di-Vorlage'!$B$9 -> 6. Lek. |
B43: 🗂 Admin | C43: ='Di-Vorlage'!$C$9 -> 0 | D43: ='Di-Vorlage'!$D$9 -> 0
B44: 🎯 Lernziele
B45: 🚀 Einstieg
...

Sheet 16.09.2026
A1: TAGESAGENDA – Mittwoch, 16.09.2026
A2: 📄 PDF exportieren: Datei → Exportieren → Als PDF/XPS | ✏️ Fach/Klasse aus Mittwoch-Vorlage (gelb) – zum Überschreiben einfach eintippen
A3: Lehrperson:
A4: Zeit | B4: Unterrichtsphase | C4: Fach ▼ | D4: Klasse ▼ | E4: Inhalt / Beschreibung | F4: Materialien | G4: Differenzierung / Notizen
A5: ◀ Zurück zur Übersicht | E5: 📋 Mittwoch-Vorlage bearbeiten
A6: =" 1. Lek. | "&'Mi-Vorlage'!$B$4 -> 1. Lek. | 07:30–08:15
B7: 🗂 Admin | C7: ='Mi-Vorlage'!$C$4 -> 0 | D7: ='Mi-Vorlage'!$D$4 -> 0
B8: 🎯 Lernziele
B9: 🚀 Einstieg
B10: 📝 Aufgaben / Erarbeitung / Vertiefung / Üben
B11: 🔒 Abschluss / Ergebnissicherung
A13: =" 2. Lek. | "&'Mi-Vorlage'!$B$5 -> 2. Lek. | 08:20–09:05
B14: 🗂 Admin | C14: ='Mi-Vorlage'!$C$5 -> 0 | D14: ='Mi-Vorlage'!$D$5 -> 0
B15: 🎯 Lernziele
B16: 🚀 Einstieg
B17: 📝 Aufgaben / Erarbeitung / Vertiefung / Üben
B18: 🔒 Abschluss / Ergebnissicherung
A20: =" 3. Lek. | "&'Mi-Vorlage'!$B$6 -> 3. Lek. | 09:10–09:55
B21: 🗂 Admin | C21: ='Mi-Vorlage'!$C$6 -> 0 | D21: ='Mi-Vorlage'!$D$6 -> 0
B22: 🎯 Lernziele
B23: 🚀 Einstieg
B24: 📝 Aufgaben / Erarbeitung / Vertiefung / Üben
B25: 🔒 Abschluss / Ergebnissicherung
A27: =" 4. Lek. | "&'Mi-Vorlage'!$B$7 -> 4. Lek. | 10:25–11:10
B28: 🗂 Admin | C28: ='Mi-Vorlage'!$C$7 -> 0 | D28: ='Mi-Vorlage'!$D$7 -> 0
B29: 🎯 Lernziele
B30: 🚀 Einstieg
B31: 📝 Aufgaben / Erarbeitung / Vertiefung / Üben
B32: 🔒 Abschluss / Ergebnissicherung
A34: =" 5. Lek. | "&'Mi-Vorlage'!$B$8 -> 5. Lek. | 11:15–12:00
B35: 🗂 Admin | C35: ='Mi-Vorlage'!$C$8 -> 0 | D35: ='Mi-Vorlage'!$D$8 -> 0
B36: 🎯 Lernziele
B37: 🚀 Einstieg
B38: 📝 Aufgaben / Erarbeitung / Vertiefung / Üben
B39: 🔒 Abschluss / Ergebnissicherung
A41: ── MITTAGSPAUSE
A42: =" 6. Lek. | "&'Mi-Vorlage'!$B$9 -> 6. Lek. |
B43: 🗂 Admin | C43: ='Mi-Vorlage'!$C$9 -> 0 | D43: ='Mi-Vorlage'!$D$9 -> 0
B44: 🎯 Lernziele
B45: 🚀 Einstieg
...

Sheet 17.09.2026
A1: TAGESAGENDA – Donnerstag, 17.09.2026
A2: 📄 PDF exportieren: Datei → Exportieren → Als PDF/XPS | ✏️ Fach/Klasse aus Donnerstag-Vorlage (gelb) – zum Überschreiben einfach eintippen
A3: Lehrperson:
A4: Zeit | B4: Unterrichtsphase | C4: Fach ▼ | D4: Klasse ▼ | E4: Inhalt / Beschreibung | F4: Materialien | G4: Differenzierung / Notizen
A5: ◀ Zurück zur Übersicht | E5: 📋 Donnerstag-Vorlage bearbeiten
A6: =" 1. Lek. | "&'Do-Vorlage'!$B$4 -> 1. Lek. | 07:30–08:15
B7: 🗂 Admin | C7: ='Do-Vorlage'!$C$4 -> 0 | D7: ='Do-Vorlage'!$D$4 -> 0
B8: 🎯 Lernziele
B9: 🚀 Einstieg
B10: 📝 Aufgaben / Erarbeitung / Vertiefung / Üben
B11: 🔒 Abschluss / Ergebnissicherung
A13: =" 2. Lek. | "&'Do-Vorlage'!$B$5 -> 2. Lek. | 08:20–09:05
B14: 🗂 Admin | C14: ='Do-Vorlage'!$C$5 -> 0 | D14: ='Do-Vorlage'!$D$5 -> 0
B15: 🎯 Lernziele
B16: 🚀 Einstieg
B17: 📝 Aufgaben / Erarbeitung / Vertiefung / Üben
B18: 🔒 Abschluss / Ergebnissicherung
A20: =" 3. Lek. | "&'Do-Vorlage'!$B$6 -> 3. Lek. | 09:10–09:55
B21: 🗂 Admin | C21: ='Do-Vorlage'!$C$6 -> 0 | D21: ='Do-Vorlage'!$D$6 -> 0
B22: 🎯 Lernziele
B23: 🚀 Einstieg
B24: 📝 Aufgaben / Erarbeitung / Vertiefung / Üben
B25: 🔒 Abschluss / Ergebnissicherung
A27: =" 4. Lek. | "&'Do-Vorlage'!$B$7 -> 4. Lek. | 10:25–11:10
B28: 🗂 Admin | C28: ='Do-Vorlage'!$C$7 -> 0 | D28: ='Do-Vorlage'!$D$7 -> 0
B29: 🎯 Lernziele
B30: 🚀 Einstieg
